Workbook

Sheet D1平日修訂版
A1: D1 | B1: 行政區 | C1: 場站名稱 | D1: 合約柱數 | E1: 夜班配置(平日) | G1: 2.0綁車 | H1: 早班配置(平日) | J1: 2.0綁車 | K1: 晚班配置(平日) | M1: 2.0綁車
A2: 501501001 | B2: 台東市 | C2: 臺東縣政府文化處圖書館 | D2: 55 | E2: 5 | F2: 15 | H2: 2 | I2: 8 | K2: 2 | L2: 8
A3: 501501002 | B3: 台東市 | C3: 臺東轉運站 | D3: 60 | E3: 10 | F3: 10 | H3: 5 | I3: 10 | K3: 5 | L3: 10
A4: 501501003 | B4: 台東市 | C4: 臺東市公所 | D4: 20 | E4: 5 | F4: 5 | H4: 2 | I4: 5 | K4: 2 | L4: 5
A5: 501501004 | B5: 台東市 | C5: 臺東縣政府 | D5: 25 | E5: 5 | F5: 5 | H5: 2 | I5: 5 | K5: 2 | L5: 5
A6: 501501006 | B6: 台東市 | C6: 微光市集 | D6: 30 | E6: 5 | F6: 5 | H6: 3 | I6: 5 | K6: 3 | L6: 5
A7: 501501008 | B7: 台東市 | C7: 臺東縣立體育場 | D7: 20 | E7: 4 | F7: 4 | H7: 2 | I7: 3 | K7: 2 | L7: 3
A8: 501501009 | B8: 台東市 | C8: 東海國宅 | D8: 17 | E8: 5 | F8: 5 | H8: 5 | I8: 5 | K8: 2 | L8: 3
A9: 501501010 | B9: 台東市 | C9: 東海運動公園 | D9: 15 | E9: 4 | F9: 4 | H9: 2 | I9: 4 | K9: 2 | L9: 3
A10: 501501011 | B10: 台東市 | C10: 臺東火車站 | D10: 50 | E10: 10 | F10: 20 | H10: 10 | I10: 20 | K10: 10 | L10: 20
A11: 501501012 | B11: 台東市 | C11: 臺東棒球村第一棒球場 | D11: 20 | E11: 4 | F11: 4 | H11: 2 | I11: 4 | K11: 2 | L11: 4
A12: 501501013 | B12: 台東市 | C12: 寶桑國中活動中心 | D12: 15 | E12: 3 | F12: 3 | H12: 5 | I12: 5 | J12: 10 | K12: 5 | L12: 5 | M12: 10
A13: 501501014 | B13: 台東市 | C13: 生日蛋糕公園 | D13: 18 | E13: 4 | F13: 4 | H13: 4 | I13: 4 | K13: 4 | L13: 4
A14: 501501015 | B14: 台東市 | C14: 國立臺東女子高級中學 | D14: 39 | E14: 10 | F14: 5 | G14: 10 | H14: 20 | I14: 10 | J14: 30 | K14: 20 | L14: 10 | M14: 30
A15: 501501016 | B15: 台東市 | C15: 仁義北路與豐里橋交叉口 | D15: 20 | E15: 5 | F15: 5 | H15: 2 | I15: 5 | K15: 3 | L15: 3
A16: 501501017 | B16: 台東市 | C16: 臺東公園 | D16: 20 | E16: 4 | F16: 4 | H16: 2 | I16: 4 | K16: 2 | L16: 4
A17: 501501018 | B17: 台東市 | C17: 兒福聯盟臺東工作站 | D17: 27 | E17: 5 | F17: 5 | H17: 2 | I17: 5 | K17: 2 | L17: 5
A18: 501501019 | B18: 台東市 | C18: 國立臺東高級商業職業學校 | D18: 15 | E18: 4 | F18: 4 | H18: 3 | I18: 4 | J18: 10 | K18: 3 | L18: 4 | M18: 10
A19: 501501021 | B19: 台東市 | C19: 寶桑國小 | D19: 15 | E19: 4 | F19: 4 | H19: 3 | I19: 5 | K19: 3 | L19: 5
A20: 501501022 | B20: 台東市 | C20: 臺東縣環境保護局 | D20: 15 | E20: 4 | F20: 4 | H20: 2 | I20: 4 | K20: 2 | L20: 4
A21: 501501023 | B21: 台東市 | C21: 臺東市漢中街公園 | D21: 12 | E21: 3 | F21: 3 | H21: 2 | I21: 3 | K21: 2 | L21: 3
A22: 501501024 | B22: 台東市 | C22: 臺東聖母醫院 | D22: 18 | E22: 3 | F22: 3 | H22: 3 | I22: 3 | K22: 3 | L22: 3
A23: 501501025 | B23: 台東市 | C23: 柳州街停車場 | D23: 20 | E23: 7 | F23: 7 | H23: 7 | I23: 7 | K23: 2 | L23: 2
A24: 501501026 | B24: 台東市 | C24: 仁義北路河堤涼亭 | D24: 20 | E24: 4 | F24: 4 | H24: 2 | I24: 4 | K24: 2 | L24: 4
A25: 501501027 | B25: 台東市 | C25: 國立臺東高級中學學生宿舍 | D25: 20 | E25: 6 | F25: 5 | H25: 2 | I25: 5 | K25: 2 | L25: 5
A26: 501501029 | B26: 台東市 | C26: 桂林南路238巷與中華路一段719巷口 | D26: 18 | E26: 2 | F26: 2 | H26: 4 | I26: 4 | J26: 15 | K26: 4 | L26: 4 | M26: 15
A27: 501501030 | B27: 台東市 | C27: 臺東縣私立公東高級工業職業學校 | D27: 20 | E27: 4 | F27: 4 | H27: 4 | I27: 4 | K27: 4 | L27: 4
A28: 501501031 | B28: 台東市 | C28: 四維夜市 | D28: 17 | E28: 4 | F28: 4 | H28: 4 | I28: 3 | K28: 4 | L28: 3
A29: 501501032 | B29: 台東市 | C29: 四維路三段與傳廣路交叉口 | D29: 16 | E29: 4 | F29: 4 | H29: 2 | I29: 3 | K29: 2 | L29: 3
A30: 501501033 | B30: 台東市 | C30: 四維路三段與泰安街(西側) | D30: 20 | E30: 4 | F30: 4 | H30: 2 | I30: 3 | K30: 2 | L30: 3
A31: 501501034 | B31: 台東市 | C31: 開封街鐵馬道 | D31: 12 | E31: 5 | F31: 4 | H31: 5 | I31: 4 | K31: 5 | L31: 4
A32: 501501035 | B32: 台東市 | C32: 四維路三段與長安街交叉口 | D32: 13 | E32: 3 | F32: 3 | H32: 4 | I32: 3 | J32: 10 | K32: 4 | L32: 3 | M32: 10
A33: 501501036 | B33: 台東市 | C33: 臺東縣立新生國民中學 | D33: 23 | E33: 4 | F33: 4 | H33: 8 | I33: 7 | J33: 10 | K33: 8 | L33: 7 | M33: 10
A34: 501501037 | B34: 台東市 | C34: 臺東縣臺東市康樂國小 | D34: 20 | E34: 4 | F34: 4 | H34: 2 | I34: 4 | K34: 2 | L34: 4
A35: 501501038 | B35: 台東市 | C35: 臺東專科學校宿舍 | D35: 15 | E35: 6 | F35: 6 | G35: 8 | H35: 6 | I35: 6 | J35: 8 | K35: 6 | L35: 6 | M35: 8
A36: 501501039 | B36: 台東市 | C36: 臺東專科學校 | D36: 30 | E36: 2 | F36: 2 | H36: 1 | I36: 20 | J36: 10+10 | K36: 1 | L36: 20 | M36: 10+10
A37: 501501040 | B37: 台東市 | C37: 正氣公園 | D37: 16 | E37: 3 | F37: 3 | H37: 3 | I37: 3 | K37: 3 | L37: 3
A38: 501501041 | B38: 台東市 | C38: 長沙街溜冰場 | D38: 28 | E38: 8 | F38: 8 | H38: 6 | I38: 6 | K38: 6 | L38: 6
A39: 501501042 | B39: 台東市 | C39: 臺東航空站 | D39: 20 | E39: 6 | F39: 2 | H39: 6 | I39: 2 | K39: 6 | L39: 2
A40: 501501043 | B40: 台東市 | C40: 娜路彎大酒店 | D40: 30 | E40: 5 | F40: 10 | H40: 5 | I40: 5 | K40: 5 | L40: 5
...

Sheet 「D1平日」修訂版0217
A1: D1 | B1: 行政區 | C1: 場站名稱 | D1: 合約柱數 | E1: 夜班配置(平日) | G1: 2.0綁車 | H1: 早班配置(平日) | J1: 2.0綁車 | K1: 晚班配置(平日) | M1: 2.0綁車
A2: 501501001 | B2: 台東市 | C2: 臺東縣政府文化處圖書館 | D2: 55 | E2: 25 | F2: 8 | H2: 2 | I2: 8 | K2: 2 | L2: 8
A3: 501501002 | B3: 台東市 | C3: 臺東轉運站 | D3: 60 | E3: 10 | F3: 15 | H3: 5 | I3: 10 | K3: 5 | L3: 10
A4: 501501003 | B4: 台東市 | C4: 臺東市公所 | D4: 20 | E4: 5 | F4: 5 | H4: 2 | I4: 5 | K4: 2 | L4: 5
A5: 501501004 | B5: 台東市 | C5: 臺東縣政府 | D5: 25 | E5: 5 | F5: 7 | H5: 2 | I5: 7 | K5: 2 | L5: 7
A6: 501501006 | B6: 台東市 | C6: 微光市集 | D6: 30 | E6: 5 | F6: 5 | H6: 3 | I6: 5 | K6: 3 | L6: 5
A7: 501501008 | B7: 台東市 | C7: 臺東縣立體育場 | D7: 20 | E7: 4 | F7: 4 | H7: 2 | I7: 3 | K7: 2 | L7: 3
A8: 501501009 | B8: 台東市 | C8: 東海國宅 | D8: 17 | E8: 5 | F8: 5 | H8: 3 | I8: 3 | K8: 2 | L8: 3
A9: 501501010 | B9: 台東市 | C9: 東海運動公園 | D9: 15 | E9: 4 | F9: 4 | H9: 2 | I9: 4 | K9: 2 | L9: 3
A10: 501501011 | B10: 台東市 | C10: 臺東火車站 | D10: 50 | E10: 5 | F10: 20 | H10: 5 | I10: 20 | K10: 5 | L10: 20
A11: 501501012 | B11: 台東市 | C11: 臺東棒球村第一棒球場 | D11: 20 | E11: 4 | F11: 4 | H11: 2 | I11: 4 | K11: 2 | L11: 4
A12: 501501013 | B12: 台東市 | C12: 寶桑國中活動中心 | D12: 15 | E12: 3 | F12: 3 | H12: 5 | I12: 5 | J12: 10 | K12: 5 | L12: 5 | M12: 10
A13: 501501014 | B13: 台東市 | C13: 生日蛋糕公園 | D13: 18 | E13: 4 | F13: 4 | H13: 3 | I13: 2 | K13: 3 | L13: 2
A14: 501501015 | B14: 台東市 | C14: 國立臺東女子高級中學 | D14: 39 | E14: 10 | F14: 5 | G14: 10 | H14: 10 | I14: 20 | J14: 30 | K14: 10 | L14: 20 | M14: 30
A15: 501501016 | B15: 台東市 | C15: 仁義北路與豐里橋交叉口 | D15: 20 | E15: 2 | F15: 5 | H15: 2 | I15: 5 | K15: 3 | L15: 3
A16: 501501017 | B16: 台東市 | C16: 臺東公園 | D16: 20 | E16: 2 | F16: 3 | H16: 2 | I16: 3 | K16: 2 | L16: 3
A17: 501501018 | B17: 台東市 | C17: 兒福聯盟臺東工作站 | D17: 27 | E17: 5 | F17: 7 | H17: 2 | I17: 7 | K17: 2 | L17: 7
A18: 501501019 | B18: 台東市 | C18: 國立臺東高級商業職業學校 | D18: 15 | E18: 2 | F18: 3 | H18: 3 | I18: 4 | J18: 10 | K18: 3 | L18: 4 | M18: 10
A19: 501501021 | B19: 台東市 | C19: 寶桑國小 | D19: 15 | E19: 3 | F19: 3 | H19: 3 | I19: 5 | K19: 3 | L19: 5
A20: 501501022 | B20: 台東市 | C20: 臺東縣環境保護局 | D20: 15 | E20: 4 | F20: 4 | H20: 2 | I20: 4 | K20: 2 | L20: 4
A21: 501501023 | B21: 台東市 | C21: 臺東市漢中街公園 | D21: 12 | E21: 3 | F21: 3 | H21: 2 | I21: 3 | K21: 2 | L21: 3
A22: 501501024 | B22: 台東市 | C22: 臺東聖母醫院 | D22: 18 | E22: 3 | F22: 3 | H22: 2 | I22: 3 | K22: 2 | L22: 3
A23: 501501025 | B23: 台東市 | C23: 柳州街停車場 | D23: 20 | E23: 2 | F23: 12 | H23: 2 | I23: 4 | K23: 2 | L23: 4
A24: 501501026 | B24: 台東市 | C24: 仁義北路河堤涼亭 | D24: 20 | E24: 4 | F24: 4 | H24: 2 | I24: 4 | K24: 2 | L24: 4
A25: 501501027 | B25: 台東市 | C25: 國立臺東高級中學學生宿舍 | D25: 20 | E25: 3 | F25: 5 | H25: 3 | I25: 5 | K25: 6 | L25: 5
A26: 501501029 | B26: 台東市 | C26: 桂林南路238巷與中華路一段719巷口 | D26: 18 | E26: 2 | F26: 2 | H26: 4 | I26: 4 | J26: 15 | K26: 4 | L26: 4 | M26: 15
A27: 501501030 | B27: 台東市 | C27: 臺東縣私立公東高級工業職業學校 | D27: 20 | E27: 4 | F27: 4 | H27: 4 | I27: 4 | K27: 4 | L27: 4
A28: 501501031 | B28: 台東市 | C28: 四維夜市 | D28: 17 | E28: 4 | F28: 4 | H28: 3 | I28: 3 | K28: 3 | L28: 3
A29: 501501032 | B29: 台東市 | C29: 四維路三段與傳廣路交叉口 | D29: 16 | E29: 4 | F29: 4 | H29: 2 | I29: 3 | K29: 2 | L29: 3
A30: 501501033 | B30: 台東市 | C30: 四維路三段與泰安街(西側) | D30: 20 | E30: 2 | F30: 3 | H30: 2 | I30: 3 | K30: 2 | L30: 3
A31: 501501034 | B31: 台東市 | C31: 開封街鐵馬道 | D31: 12 | E31: 3 | F31: 3 | H31: 3 | I31: 4 | K31: 3 | L31: 4
A32: 501501035 | B32: 台東市 | C32: 四維路三段與長安街交叉口 | D32: 13 | E32: 3 | F32: 3 | H32: 4 | I32: 3 | J32: 10 | K32: 4 | L32: 3 | M32: 10
A33: 501501036 | B33: 台東市 | C33: 臺東縣立新生國民中學 | D33: 23 | E33: 4 | F33: 4 | H33: 8 | I33: 7 | J33: 10 | K33: 8 | L33: 7 | M33: 10
A34: 501501037 | B34: 台東市 | C34: 臺東縣臺東市康樂國小 | D34: 20 | E34: 2 | F34: 4 | H34: 2 | I34: 4 | K34: 2 | L34: 4
A35: 501501038 | B35: 台東市 | C35: 臺東專科學校宿舍 | D35: 15 | E35: 2 | F35: 8 | G35: 8 | H35: 2 | I35: 8 | J35: 8 | K35: 2 | L35: 8 | M35: 8
A36: 501501039 | B36: 台東市 | C36: 臺東專科學校 | D36: 30 | E36: 2 | F36: 2 | H36: 1 | I36: 20 | J36: 10+10 | K36: 1 | L36: 20 | M36: 10+10
A37: 501501040 | B37: 台東市 | C37: 正氣公園 | D37: 16 | E37: 2 | F37: 3 | H37: 2 | I37: 3 | K37: 3 | L37: 3
A38: 501501041 | B38: 台東市 | C38: 長沙街溜冰場 | D38: 28 | E38: 7 | F38: 8 | H38: 5 | I38: 6 | K38: 4 | L38: 4
A39: 501501042 | B39: 台東市 | C39: 臺東航空站 | D39: 20 | E39: 5 | F39: 0 | H39: 5 | I39: 0 | K39: 5 | L39: 0
A40: 501501043 | B40: 台東市 | C40: 娜路彎大酒店 | D40: 30 | E40: 4 | F40: 10 | H40: 4 | I40: 5 | K40: 4 | L40: 5
...

Sheet 115_D1暑假配置表
A1: D1 | B1: 行政區 | C1: 場站名稱 | D1: 合約柱數 | E1: 夜班配置(暑假) | G1: 2.0綁車 | H1: 早班配置(暑假) | J1: 2.0綁車 | K1: 晚班配置(暑假) | M1: 2.0綁車
A2: 501501001 | B2: 台東市 | C2: 臺東縣政府文化處圖書館 | D2: 55 | E2: 12 | F2: 8 | H2: 2 | I2: 8 | K2: 2 | L2: 8
A3: 501501002 | B3: 台東市 | C3: 臺東轉運站 | D3: 60 | E3: 10 | F3: 15 | H3: 10 | I3: 10 | K3: 5 | L3: 10
A4: 501501003 | B4: 台東市 | C4: 臺東市公所 | D4: 20 | E4: 5 | F4: 5 | H4: 3 | I4: 5 | K4: 3 | L4: 5
A5: 501501004 | B5: 台東市 | C5: 臺東縣政府 | D5: 25 | E5: 5 | F5: 7 | H5: 3 | I5: 7 | K5: 2 | L5: 5
A6: 501501006 | B6: 台東市 | C6: 微光市集 | D6: 30 | E6: 7 | F6: 8 | H6: 3 | I6: 5 | K6: 3 | L6: 5
A7: 501501008 | B7: 台東市 | C7: 臺東縣立體育場 | D7: 20 | E7: 4 | F7: 4 | H7: 2 | I7: 3 | K7: 2 | L7: 3
A8: 501501009 | B8: 台東市 | C8: 東海國宅 | D8: 17 | E8: 2 | F8: 5 | H8: 2 | I8: 3 | K8: 2 | L8: 3
A9: 501501010 | B9: 台東市 | C9: 東海運動公園 | D9: 15 | E9: 2 | F9: 4 | H9: 2 | I9: 4 | K9: 2 | L9: 2
A10: 501501011 | B10: 台東市 | C10: 臺東火車站 | D10: 50 | E10: 5 | F10: 20 | G10: 20 | H10: 5 | I10: 20 | J10: 20 | K10: 5 | L10: 20 | M10: 20
A11: 501501012 | B11: 台東市 | C11: 臺東棒球村第一棒球場 | D11: 20 | E11: 5 | F11: 5 | H11: 2 | I11: 4 | K11: 2 | L11: 4
A12: 501501013 | B12: 台東市 | C12: 寶桑國中活動中心 | D12: 15 | E12: 3 | F12: 3 | H12: 3 | I12: 3 | K12: 3 | L12: 3
A13: 501501014 | B13: 台東市 | C13: 生日蛋糕公園 | D13: 18 | E13: 5 | F13: 5 | H13: 3 | I13: 3 | K13: 3 | L13: 3
A14: 501501015 | B14: 台東市 | C14: 國立臺東女子高級中學 | D14: 39 | E14: 3 | F14: 7 | H14: 3 | I14: 7 | K14: 3 | L14: 7
A15: 501501016 | B15: 台東市 | C15: 仁義北路與豐里橋交叉口 | D15: 20 | E15: 2 | F15: 5 | H15: 2 | I15: 5 | K15: 3 | L15: 3
A16: 501501017 | B16: 台東市 | C16: 臺東公園 | D16: 20 | E16: 3 | F16: 2 | H16: 3 | I16: 1 | K16: 3 | L16: 1
A17: 501501018 | B17: 台東市 | C17: 兒福聯盟臺東工作站 | D17: 27 | E17: 6 | F17: 6 | H17: 3 | I17: 5 | K17: 3 | L17: 3
A18: 501501019 | B18: 台東市 | C18: 國立臺東高級商業職業學校 | D18: 15 | E18: 4 | F18: 4 | H18: 4 | I18: 4 | K18: 4 | L18: 4
A19: 501501021 | B19: 台東市 | C19: 寶桑國小 | D19: 15 | E19: 3 | F19: 3 | H19: 3 | I19: 5 | K19: 3 | L19: 5
A20: 501501022 | B20: 台東市 | C20: 臺東縣環境保護局 | D20: 15 | E20: 4 | F20: 4 | H20: 5 | I20: 5 | K20: 2 | L20: 4
A21: 501501023 | B21: 台東市 | C21: 臺東市漢中街公園 | D21: 12 | E21: 3 | F21: 3 | H21: 2 | I21: 3 | K21: 2 | L21: 3
A22: 501501024 | B22: 台東市 | C22: 臺東聖母醫院 | D22: 18 | E22: 3 | F22: 3 | H22: 2 | I22: 3 | K22: 2 | L22: 3
... A89: 501502008 | B89: 卑南鄉 | C89: 知本國家森林遊樂區 | D89: 24 | E89: 2 | F89: 4 | H89: 2 | I89: 4 | K89: 2 | L89: 4
D90: =SUM(D2:D89) -> 1959 | E90: =SUM(E2:E89) -> 319 | F90: =SUM(F2:F89) -> 379 | G90: =SUM(G2:G89) -> 20 | H90: =SUM(H2:H89) -> 268 | I90: =SUM(I2:I89) -> 340 | J90: =SUM(J2:J89) -> 20 | K90: =SUM(K2:K89) -> 239 | ... M90: =SUM(M2:M89) -> 20

Sheet 115_D2、D3暑假配置表
A1: D2 | B1: 行政區 | C1: 場站名稱 | D1: 合約柱數 | E1: 夜班配置(暑假) | G1: 2.0綁車 | H1: 早班配置(暑假) | J1: 2.0綁車 | K1: 晚班配置(暑假) | M1: 2.0綁車
A2: 501502003 | B2: 卑南鄉 | C2: 卑南鄉老人文康中心 | D2: 15 | E2: 3 | F2: 0 | H2: 3 | I2: 0 | K2: 3 | L2: 0
A3: 501503001 | B3: 鹿野鄉 | C3: 瑞源車站 | D3: 20 | E3: 2 | F3: 4 | H3: 2 | I3: 4 | K3: 2 | L3: 4
A4: 501503002 | B4: 鹿野鄉 | C4: 永安農產品銷售中心 | D4: 23 | E4: 4 | F4: 0 | H4: 4 | I4: 0 | K4: 4 | L4: 0
A5: 501503003 | B5: 鹿野鄉 | C5: 龍田大草坪 | D5: 30 | E5: 2 | F5: 6 | H5: 2 | I5: 6 | K5: 2 | L5: 6
A6: 501503004 | B6: 鹿野鄉 | C6: 鹿野車站 | D6: 49 | E6: 2 | F6: 10 | H6: 2 | I6: 8 | K6: 2 | L6: 6
A7: 501503005 | B7: 鹿野鄉 | C7: 福鹿山休閒農莊 | D7: 22 | E7: 1 | F7: 6 | H7: 1 | I7: 6 | K7: 1 | L7: 6
A8: 501503006 | B8: 鹿野鄉 | C8: 鹿野地區農會 | D8: 24 | E8: 2 | F8: 2 | H8: 2 | I8: 2 | K8: 2 | L8: 2
A9: 501503007 | B9: 鹿野鄉 | C9: 龍田老人會館 | D9: 20 | E9: 2 | F9: 2 | H9: 2 | I9: 4 | K9: 2 | L9: 4
A10: 501503008 | B10: 鹿野鄉 | C10: 永安環教中心 | D10: 20 | E10: 4 | F10: 0 | H10: 4 | I10: 0 | K10: 4 | L10: 0
A11: 501504001 | B11: 關山鎮 | C11: 關山車站 | D11: 60 | E11: 15 | F11: 10 | H11: 10 | I11: 10 | K11: 10 | L11: 10
A12: 501504003 | B12: 關山鎮 | C12: 米國學校 | D12: 20 | E12: 3 | F12: 3 | H12: 2 | I12: 2 | K12: 2 | L12: 2
A13: 501504004 | B13: 關山鎮 | C13: 關山工商 | D13: 30 | E13: 3 | F13: 4 | H13: 2 | I13: 4 | K13: 2 | L13: 5
... A23: 501505007 | B23: 池上鄉 | C23: 日暉國際渡假村 | D23: 30 | E23: 14 | F23: 8 | H23: 6 | I23: 4 | K23: 6 | L23: 4
A24: 501599003 | B24: 池上鄉 | C24: 池上維調 | G24: 10 | J24: 10 | M24: 10
D66: =SUM(D2:D65) -> 631 | E66: =SUM(E2:E65) -> 158 | F66: =SUM(F2:F65) -> 131 | G66: =SUM(G2:G65) -> 10 | H66: =SUM(H2:H65) -> 96 | I66: =SUM(I2:I65) -> 86 | J66: =SUM(J2:J65) -> 10 | K66: =SUM(K2:K65) -> 94 | ... M66: =SUM(M2:M65) -> 10
A69: D3 | B69: 行政區 | C69: 場站名稱 | D69: 合約柱數 | E69: 夜班配置(暑假) | G69: 2.0綁車 | H69: 早班配置(暑假) | J69: 2.0綁車 | K69: 晚班配置(暑假) | M69: 2.0綁車
A70: 501502005 | B70: 卑南鄉 | C70: 富山護漁區 | D70: 15 | E70: 3 | F70: 0 | H70: 3 | I70: 0 | K70: 3 | L70: 0
A71: 501506001 | B71: 成功鎮 | C71: 成功漁港 | D71: 15 | E71: 7 | F71: 0 | H71: 7 | I71: 0 | K71: 7 | L71: 0
A72: 501506002 | B72: 成功鎮 | C72: 成功鎮公所 | D72: 20 | E72: 4 | F72: 3 | H72: 4 | I72: 3 | K72: 4 | L72: 3
A73: 501506003 | B73: 成功鎮 | C73: 成功豆花 | D73: 20 | E73: 4 | F73: 3 | H73: 4 | I73: 3 | K73: 4 | L73: 3
A74: 501506005 | B74: 成功鎮 | C74: 東管處停車場 | D74: 24 | E74: 3 | F74: 0 | H74: 3 | I74: 0 | K74: 3 | L74: 0
A75: 501506006 | B75: 成功鎮 | C75: 三仙台 | D75: 30 | E75: 7 | F75: 0 | H75: 7 | I75: 0 | K75: 7 | L75: 0
A76: 501506007 | B76: 成功鎮 | C76: 成功海濱公園 | D76: 30 | E76: 4 | F76: 5 | H76: 4 | I76: 5 | K76: 4 | L76: 5
A77: 501509001 | B77: 東河鄉 | C77: 都蘭舊糖廠 | D77: 28 | E77: 4 | F77: 4 | H77: 4 | I77: 4 | K77: 4 | L77: 4
A78: 501509002 | B78: 東河鄉 | C78: 東河消防隊 | D78: 20 | E78: 3 | F78: 0 | H78: 3 | I78: 0 | K78: 3 | L78: 0
A79: 501506004 | B79: 成功鎮 | C79: 成功消防隊 | D79: 28 | E79: 4 | F79: 2 | H79: 4 | I79: 2 | K79: 4 | L79: 2
D80: =SUM(D70:D79) -> 230 | E80: =SUM(E70:E79) -> 43 | F80: =SUM(F70:F79) -> 17 | G80: =SUM(G70:G78) -> 0 | H80: =SUM(H70:H79) -> 43 | I80: =SUM(I70:I79) -> 17 | J80: =SUM(J70:J78) -> 0 | K80: =SUM(K70:K79) -> 43 | L80: =SUM(L70:L79) -> 17 | M80: =SUM(M70:M78) -> 0

Sheet 「D1平日」0423
A1: D1 | B1: 行政區 | C1: 場站名稱 | D1: 合約柱數 | E1: 夜班配置(平日) | G1: 2.0綁車 | H1: 早班配置(平日) | J1: 2.0綁車 | K1: 晚班配置(平日) | M1: 2.0綁車
A2: 501501001 | B2: 台東市 | C2: 臺東縣政府文化處圖書館 | D2: 55 | E2: 15 | F2: 8 | H2: 2 | I2: 8 | K2: 2 | L2: 8
A3: 501501002 | B3: 台東市 | C3: 臺東轉運站 | D3: 60 | E3: 10 | F3: 15 | H3: 5 | I3: 10 | K3: 5 | L3: 10
A4: 501501003 | B4: 台東市 | C4: 臺東市公所 | D4: 20 | E4: 5 | F4: 5 | H4: 2 | I4: 5 | K4: 2 | L4: 5
A5: 501501004 | B5: 台東市 | C5: 臺東縣政府 | D5: 25 | E5: 5 | F5: 7 | H5: 2 | I5: 7 | K5: 2 | L5: 7
A6: 501501006 | B6: 台東市 | C6: 微光市集 | D6: 30 | E6: 7 | F6: 8 | H6: 3 | I6: 5 | K6: 3 | L6: 5
A7: 501501008 | B7: 台東市 | C7: 臺東縣立體育場 | D7: 20 | E7: 4 | F7: 4 | H7: 2 | I7: 3 | K7: 2 | L7: 3
A8: 501501009 | B8: 台東市 | C8: 東海國宅 | D8: 17 | E8: 5 | F8: 5 | H8: 3 | I8: 3 | K8: 2 | L8: 3
A9: 501501010 | B9: 台東市 | C9: 東海運動公園 | D9: 15 | E9: 4 | F9: 4 | H9: 2 | I9: 4 | K9: 2 | L9: 3
A10: 501501011 | B10: 台東市 | C10: 臺東火車站 | D10: 50 | E10: 5 | F10: 20 | H10: 5 | I10: 20 | K10: 5 | L10: 20
A11: 501501012 | B11: 台東市 | C11: 臺東棒球村第一棒球場 | D11: 20 | E11: 4 | F11: 4 | H11: 2 | I11: 4 | K11: 2 | L11: 4
A12: 501501013 | B12: 台東市 | C12: 寶桑國中活動中心 | D12: 15 | E12: 3 | F12: 3 | H12: 5 | I12: 5 | J12: 10 | K12: 5 | L12: 5 | M12: 10
A13: 501501014 | B13: 台東市 | C13: 生日蛋糕公園 | D13: 18 | E13: 4 | F13: 4 | H13: 3 | I13: 2 | K13: 3 | L13: 2
A14: 501501015 | B14: 台東市 | C14: 國立臺東女子高級中學 | D14: 39 | E14: 10 | F14: 5 | G14: 10 | H14: 5 | I14: 20 | J14: 30 | K14: 5 | L14: 20 | M14: 30
A15: 501501016 | B15: 台東市 | C15: 仁義北路與豐里橋交叉口 | D15: 20 | E15: 2 | F15: 5 | H15: 2 | I15: 5 | K15: 3 | L15: 3
A16: 501501017 | B16: 台東市 | C16: 臺東公園 | D16: 20 | E16: 3 | F16: 0 | H16: 3 | I16: 0 | K16: 3 | L16: 0
A17: 501501018 | B17: 台東市 | C17: 兒福聯盟臺東工作站 | D17: 27 | E17: 5 | F17: 7 | H17: 2 | I17: 7 | K17: 2 | L17: 7
A18: 501501019 | B18: 台東市 | C18: 國立臺東高級商業職業學校 | D18: 15 | E18: 4 | F18: 4 | H18: 4 | I18: 4 | J18: 5 | K18: 4 | L18: 4 | M18: 5
A19: 501501021 | B19: 台東市 | C19: 寶桑國小 | D19: 15 | E19: 3 | F19: 3 | H19: 3 | I19: 5 | K19: 3 | L19: 5
A20: 501501022 | B20: 台東市 | C20: 臺東縣環境保護局 | D20: 15 | E20: 4 | F20: 4 | H20: 2 | I20: 4 | K20: 2 | L20: 4
A21: 501501023 | B21: 台東市 | C21: 臺東市漢中街公園 | D21: 12 | E21: 3 | F21: 3 | H21: 2 | I21: 3 | K21: 2 | L21: 3
A22: 501501024 | B22: 台東市 | C22: 臺東聖母醫院 | D22: 18 | E22: 3 | F22: 3 | H22: 2 | I22: 3 | K22: 2 | L22: 3
A23: 501501025 | B23: 台東市 | C23: 柳州街停車場 | D23: 20 | E23: 2 | F23: 12 | H23: 2 | I23: 4 | K23: 2 | L23: 4
A24: 501501026 | B24: 台東市 | C24: 仁義北路河堤涼亭 | D24: 20 | E24: 4 | F24: 4 | H24: 2 | I24: 4 | K24: 2 | L24: 4
A25: 501501027 | B25: 台東市 | C25: 國立臺東高級中學學生宿舍 | D25: 20 | E25: 5 | F25: 5 | H25: 3 | I25: 5 | K25: 6 | L25: 5
A26: 501501029 | B26: 台東市 | C26: 桂林南路238巷與中華路一段719巷口 | D26: 18 | E26: 2 | F26: 4 | H26: 4 | I26: 6 | J26: 15 | K26: 4 | L26: 6 | M26: 15
A27: 501501030 | B27: 台東市 | C27: 臺東縣私立公東高級工業職業學校 | D27: 20 | E27: 4 | F27: 4 | H27: 4 | I27: 4 | K27: 4 | L27: 4
A28: 501501031 | B28: 台東市 | C28: 四維夜市 | D28: 17 | E28: 4 | F28: 4 | H28: 3 | I28: 3 | K28: 3 | L28: 3
A29: 501501032 | B29: 台東市 | C29: 四維路三段與傳廣路交叉口 | D29: 16 | E29: 4 | F29: 4 | H29: 2 | I29: 3 | K29: 2 | L29: 3
A30: 501501033 | B30: 台東市 | C30: 四維路三段與泰安街(西側) | D30: 20 | E30: 2 | F30: 3 | H30: 2 | I30: 3 | K30: 2 | L30: 3
A31: 501501034 | B31: 台東市 | C31: 開封街鐵馬道 | D31: 18 | E31: 3 | F31: 3 | H31: 6 | I31: 6 | K31: 5 | L31: 5
A32: 501501035 | B32: 台東市 | C32: 四維路三段與長安街交叉口 | D32: 13 | E32: 3 | F32: 3 | H32: 4 | I32: 4 | J32: 5 | K32: 4 | L32: 4 | M32: 5
A33: 501501036 | B33: 台東市 | C33: 臺東縣立新生國民中學 | D33: 23 | E33: 4 | F33: 4 | H33: 8 | I33: 7 | J33: 10 | K33: 8 | L33: 7 | M33: 10
A34: 501501037 | B34: 台東市 | C34: 臺東縣臺東市康樂國小 | D34: 20 | E34: 2 | F34: 4 | H34: 2 | I34: 4 | K34: 2 | L34: 4
A35: 501501038 | B35: 台東市 | C35: 臺東專科學校宿舍 | D35: 15 | E35: 2 | F35: 8 | G35: 8 | H35: 2 | I35: 8 | J35: 8 | K35: 2 | L35: 8 | M35: 8
A36: 501501039 | B36: 台東市 | C36: 臺東專科學校 | D36: 30 | E36: 2 | F36: 2 | H36: 1 | I36: 20 | J36: 10+10 | K36: 1 | L36: 20 | M36: 10+10
A37: 501501040 | B37: 台東市 | C37: 正氣公園 | D37: 16 | E37: 2 | F37: 3 | H37: 2 | I37: 3 | K37: 3 | L37: 3
A38: 501501041 | B38: 台東市 | C38: 長沙街溜冰場 | D38: 28 | E38: 7 | F38: 8 | H38: 4 | I38: 4 | K38: 4 | L38: 4
A39: 501501042 | B39: 台東市 | C39: 臺東航空站 | D39: 20 | E39: 5 | F39: 0 | H39: 5 | I39: 0 | K39: 5 | L39: 0
A40: 501501043 | B40: 台東市 | C40: 娜路彎大酒店 | D40: 30 | E40: 4 | F40: 7 | H40: 4 | I40: 5 | K40: 4 | L40: 5
...

Sheet 「D1假日」0423
A1: D1 | B1: 行政區 | C1: 場站名稱 | D1: 合約柱數 | E1: 夜班配置(假日) | G1: 2.0綁車 | H1: 早班配置(假日) | J1: 2.0綁車 | K1: 晚班配置(假日) | M1: 2.0綁車
A2: 501501001 | B2: 台東市 | C2: 臺東縣政府文化處圖書館 | D2: 55 | E2: 10 | F2: 15 | H2: 8 | I2: 8 | K2: 5 | L2: 5
A3: 501501002 | B3: 台東市 | C3: 臺東轉運站 | D3: 60 | E3: 5 | F3: 20 | H3: 5 | I3: 15 | K3: 5 | L3: 10
A4: 501501003 | B4: 台東市 | C4: 臺東市公所 | D4: 20 | E4: 3 | F4: 7 | H4: 3 | I4: 6 | K4: 3 | L4: 6
A5: 501501004 | B5: 台東市 | C5: 臺東縣政府 | D5: 25 | E5: 5 | F5: 7 | H5: 5 | I5: 6 | K5: 5 | L5: 7
A6: 501501006 | B6: 台東市 | C6: 微光市集 | D6: 30 | E6: 3 | F6: 7 | H6: 3 | I6: 7 | K6: 3 | L6: 7
A7: 501501008 | B7: 台東市 | C7: 臺東縣立體育場 | D7: 20 | E7: 3 | F7: 3 | H7: 3 | I7: 3 | K7: 3 | L7: 3
A8: 501501009 | B8: 台東市 | C8: 東海國宅 | D8: 17 | E8: 3 | F8: 4 | H8: 4 | I8: 4 | K8: 3 | L8: 3
A9: 501501010 | B9: 台東市 | C9: 東海運動公園 | D9: 15 | E9: 2 | F9: 3 | H9: 4 | I9: 3 | K9: 3 | L9: 3
A10: 501501011 | B10: 台東市 | C10: 臺東火車站 | D10: 50 | E10: 10 | F10: 20 | H10: 5 | I10: 20 | K10: 5 | L10: 15
A11: 501501012 | B11: 台東市 | C11: 臺東棒球村第一棒球場 | D11: 20 | E11: 4 | F11: 4 | H11: 5 | I11: 4 | K11: 4 | L11: 3
A12: 501501013 | B12: 台東市 | C12: 寶桑國中活動中心 | D12: 15 | E12: 3 | F12: 2 | H12: 4 | I12: 3 | K12: 6 | L12: 3
A13: 501501014 | B13: 台東市 | C13: 生日蛋糕公園 | D13: 18 | E13: 3 | F13: 3 | H13: 4 | I13: 2 | K13: 4 | L13: 2
... A43: 501501046 | B43: 台東市 | C43: 國立臺灣史前文化博物館 | D43: 30 | E43: 5 | F43: 4 | H43: 4 | I43: 5 | K43: 3 | L43: 3
A44: 501501047 | B44: 台東市 | C44: 臺東大學附屬體育高級中學 | D44: 20 | E44: 2 | F44: 12 | G44: 15 | H44: 2 | I44: 12 | J44: 12 | K44: 2 | L44: 12 | M44: 12
A45: 501501048 | B45: 台東市 | C45: 臺東表演藝術創生基地 | D45: 20 | E45: 5 | F45: 3 | H45: 5 | I45: 3 | K45: 3 | L45: 3
A46: 501501049 | B46: 台東市 | C46: 臺東市新生國民小學 | D46: 16 | E46: 3 | F46: 2 | H46: 3 | I46: 2 | K46: 3 | L46: 2
A47: 501501050 | B47: 台東市 | C47: 北町日式宿舍 | D47: 16 | E47: 3 | F47: 3 | H47: 3 | I47: 3 | K47: 3 | L47: 3
A48: 501501051 | B48: 台東市 | C48: 國立臺東大學知本校區正門 | D48: 30 | E48: 5 | F48: 5 | H48: 5 | I48: 4 | K48: 3 | L48: 3
A49: 501501052 | B49: 台東市 | C49: 卑南遺址公園 | D49: 31 | E49: 3 | F49: 3 | H49: 3 | I49: 3 | K49: 3 | L49: 3
A50: 501501053 | B50: 台東市 | C50: 新興路與北安路52巷口 | D50: 20 | E50: 5 | F50: 5 | H50: 4 | I50: 4 | K50: 4 | L50: 4
A51: 501501054 | B51: 台東市 | C51: 知本火車站 | D51: 30 | E51: 4 | F51: 9 | H51: 4 | I51: 8 | K51: 4 | L51: 8
A52: 501501055 | B52: 台東市 | C52: 臺東市仁愛國民小學 | D52: 25 | E52: 5 | F52: 5 | H52: 4 | I52: 6 | K52: 4 | L52: 6
A53: 501501056 | B53: 台東市 | C53: 南一街與南一街113巷口 | D53: 20 | E53: 3 | F53: 3 | H53: 3 | I53: 3 | K53: 3 | L53: 3
A54: 501501057 | B54: 台東市 | C54: 馬蘭部落更生聚會所 | D54: 18 | E54: 3 | F54: 0 | H54: 3 | I54: 0 | K54: 3 | L54: 0
A55: 501501058 | B55: 台東市 | C55: 統冠聯合超市(臺東店) | D55: 15 | E55: 3 | F55: 2 | H55: 3 | I55: 2 | K55: 3 | L55: 2
A56: 501501059 | B56: 台東市 | C56: 寶桑里活動中心 | D56: 34 | E56: 8 | F56: 12 | H56: 8 | I56: 12 | K56: 6 | L56: 6
... A89: 501502008 | B89: 卑南鄉 | C89: 知本國家森林遊樂區 | D89: 24 | E89: 4 | F89: 4 | H89: 4 | I89: 4 | K89: 4 | L89: 4
D90: =SUM(D2:D89) -> 1939 | E90: =SUM(E2:E89) -> 314 | F90: =SUM(F2:F89) -> 397 | G90: =SUM(G2:G89) -> 15 | H90: =SUM(H2:H89) -> 304 | I90: =SUM(I2:I89) -> 372 | J90: =SUM(J2:J89) -> 12 | K90: =SUM(K2:K89) -> 290 | ... M90: =SUM(M2:M89) -> 12

Sheet 「D2 D3平日」0307
A1: D2 | B1: 行政區 | C1: 場站名稱 | D1: 合約柱數 | E1: 夜班配置(平日) | G1: 2.0綁車 | H1: 早班配置(平日) | J1: 2.0綁車 | K1: 晚班配置(平日) | M1: 2.0綁車
A2: 501502003 | B2: 卑南鄉 | C2: 卑南鄉老人文康中心 | D2: 15 | E2: 3 | F2: 0 | H2: 3 | I2: 0 | K2: 3 | L2: 0
A3: 501503001 | B3: 鹿野鄉 | C3: 瑞源車站 | D3: 20 | E3: 3 | F3: 0 | H3: 3 | I3: 0 | K3: 3 | L3: 0
A4: 501503002 | B4: 鹿野鄉 | C4: 永安農產品銷售中心 | D4: 23 | E4: 3 | F4: 0 | H4: 3 | I4: 0 | K4: 3 | L4: 0
A5: 501503003 | B5: 鹿野鄉 | C5: 龍田大草坪 | D5: 30 | E5: 4 | F5: 0 | H5: 4 | I5: 0 | K5: 4 | L5: 0
A6: 501503004 | B6: 鹿野鄉 | C6: 鹿野車站 | D6: 49 | E6: 2 | F6: 8 | H6: 2 | I6: 6 | K6: 2 | L6: 6
A7: 501503005 | B7: 鹿野鄉 | C7: 福鹿山休閒農莊 | D7: 22 | E7: 3 | F7: 3 | H7: 3 | I7: 3 | K7: 3 | L7: 3
A8: 501503006 | B8: 鹿野鄉 | C8: 鹿野地區農會 | D8: 24 | E8: 3 | F8: 0 | H8: 3 | I8: 0 | K8: 3 | L8: 0
A9: 501503007 | B9: 鹿野鄉 | C9: 龍田老人會館 | D9: 20 | E9: 5 | F9: 0 | H9: 4 | I9: 0 | K9: 4 | L9: 0
A10: 501503008 | B10: 鹿野鄉 | C10: 永安環教中心 | D10: 20 | E10: 3 | F10: 0 | H10: 3 | I10: 0 | K10: 3 | L10: 0
A11: 501504001 | B11: 關山鎮 | C11: 關山車站 | D11: 60 | E11: 4 | F11: 15 | H11: 4 | I11: 10 | K11: 4 | L11: 10
A12: 501504003 | B12: 關山鎮 | C12: 米國學校 | D12: 20 | E12: 2 | F12: 3 | H12: 2 | I12: 2 | K12: 2 | L12: 2
A13: 501504004 | B13: 關山鎮 | C13: 關山工商 | D13: 30 | E13: 2 | F13: 3 | H13: 2 | I13: 4 | K13: 2 | L13: 5
... A23: 501505007 | B23: 池上鄉 | C23: 日暉國際渡假村 | D23: 30 | E23: 14 | F23: 7 | H23: 6 | I23: 4 | K23: 6 | L23: 4
D65: =SUM(D2:D64) -> 631 | E65: =SUM(E2:E64) -> 156 | F65: =SUM(F2:F64) -> 103 | G65: =SUM(G2:G64) -> 0 | H65: =SUM(H2:H64) -> 96 | I65: =SUM(I2:I64) -> 65 | J65: =SUM(J2:J64) -> 0 | K65: =SUM(K2:K64) -> 94 | ... M65: =SUM(M2:M64) -> 0
A68: D3 | B68: 行政區 | C68: 場站名稱 | D68: 合約柱數 | E68: 夜班配置(平日) | G68: 2.0綁車 | H68: 早班配置(平日) | J68: 2.0綁車 | K68: 晚班配置(平日) | M68: 2.0綁車
A69: 501502005 | B69: 卑南鄉 | C69: 富山護漁區 | D69: 15 | E69: 3 | F69: 0 | H69: 3 | I69: 0 | K69: 3 | L69: 0
A70: 501506001 | B70: 成功鎮 | C70: 成功漁港 | D70: 15 | E70: 7 | F70: 0 | H70: 7 | I70: 0 | K70: 7 | L70: 0
A71: 501506002 | B71: 成功鎮 | C71: 成功鎮公所 | D71: 20 | E71: 4 | F71: 3 | H71: 4 | I71: 3 | K71: 4 | L71: 3
A72: 501506003 | B72: 成功鎮 | C72: 成功豆花 | D72: 20 | E72: 4 | F72: 3 | H72: 4 | I72: 3 | K72: 4 | L72: 3
A73: 501506005 | B73: 成功鎮 | C73: 東管處停車場 | D73: 24 | E73: 3 | F73: 0 | H73: 3 | I73: 0 | K73: 3 | L73: 0
A74: 501506006 | B74: 成功鎮 | C74: 三仙台 | D74: 30 | E74: 7 | F74: 0 | H74: 7 | I74: 0 | K74: 7 | L74: 0
A75: 501506007 | B75: 成功鎮 | C75: 成功海濱公園 | D75: 30 | E75: 4 | F75: 5 | H75: 4 | I75: 5 | K75: 4 | L75: 5
A76: 501509001 | B76: 東河鄉 | C76: 都蘭舊糖廠 | D76: 28 | E76: 4 | F76: 4 | H76: 4 | I76: 4 | K76: 4 | L76: 4
A77: 501509002 | B77: 東河鄉 | C77: 東河消防隊 | D77: 20 | E77: 3 | F77: 0 | H77: 3 | I77: 0 | K77: 3 | L77: 0
A78: 501506004 | B78: 成功鎮 | C78: 成功消防隊 | D78: 28 | E78: 4 | F78: 2 | H78: 4 | I78: 2 | K78: 4 | L78: 2
D79: =SUM(D69:D77) -> 202 | E79: =SUM(E69:E78) -> 43 | F79: =SUM(F69:F78) -> 17 | G79: =SUM(G69:G77) -> 0 | H79: =SUM(H69:H78) -> 43 | I79: =SUM(I69:I78) -> 17 | J79: =SUM(J69:J77) -> 0 | K79: =SUM(K69:K78) -> 43 | L79: =SUM(L69:L78) -> 17 | M79: =SUM(M69:M77) -> 0

Sheet 「D1平日」0307
A1: 仁義北路與豐里橋交叉口 | B1: 行政區 | C1: 場站名稱 | D1: 合約柱數 | E1: 夜班配置(平日) | G1: 2.0綁車 | H1: 早班配置(平日) | J1: 2.0綁車 | K1: 晚班配置(平日) | M1: 2.0綁車
A2: 501501001 | B2: 台東市 | C2: 臺東縣政府文化處圖書館 | D2: 55 | E2: 25 | F2: 8 | H2: 2 | I2: 8 | K2: 2 | L2: 8
A3: 501501002 | B3: 台東市 | C3: 臺東轉運站 | D3: 60 | E3: 10 | F3: 15 | H3: 5 | I3: 10 | K3: 5 | L3: 10
A4: 501501003 | B4: 台東市 | C4: 臺東市公所 | D4: 20 | E4: 5 | F4: 5 | H4: 2 | I4: 5 | K4: 2 | L4: 5
A5: 501501004 | B5: 台東市 | C5: 臺東縣政府 | D5: 25 | E5: 5 | F5: 7 | H5: 2 | I5: 7 | K5: 2 | L5: 7
A6: 501501006 | B6: 台東市 | C6: 微光市集 | D6: 30 | E6: 7 | F6: 8 | H6: 3 | I6: 5 | K6: 3 | L6: 5
A7: 501501008 | B7: 台東市 | C7: 臺東縣立體育場 | D7: 20 | E7: 4 | F7: 4 | H7: 2 | I7: 3 | K7: 2 | L7: 3
A8: 501501009 | B8: 台東市 | C8: 東海國宅 | D8: 17 | E8: 5 | F8: 5 | H8: 3 | I8: 3 | K8: 2 | L8: 3
A9: 501501010 | B9: 台東市 | C9: 東海運動公園 | D9: 15 | E9: 4 | F9: 4 | H9: 2 | I9: 4 | K9: 2 | L9: 3
A10: 501501011 | B10: 台東市 | C10: 臺東火車站 | D10: 50 | E10: 5 | F10: 20 | H10: 5 | I10: 20 | K10: 5 | L10: 15
A11: 501501012 | B11: 台東市 | C11: 臺東棒球村第一棒球場 | D11: 20 | E11: 4 | F11: 4 | H11: 2 | I11: 4 | K11: 2 | L11: 4
A12: 501501013 | B12: 台東市 | C12: 寶桑國中活動中心 | D12: 15 | E12: 3 | F12: 3 | H12: 5 | I12: 5 | J12: 10 | K12: 5 | L12: 5 | M12: 10
A13: 501501014 | B13: 台東市 | C13: 生日蛋糕公園 | D13: 18 | E13: 4 | F13: 4 | H13: 3 | I13: 2 | K13: 3 | L13: 2
A14: 501501015 | B14: 台東市 | C14: 國立臺東女子高級中學 | D14: 39 | E14: 10 | F14: 5 | G14: 10 | H14: 10 | I14: 20 | J14: 30 | K14: 10 | L14: 20 | M14: 30
A15: 501501016 | B15: 台東市 | C15: 仁義北路與豐里橋交叉口 | D15: 20 | E15: 2 | F15: 5 | H15: 2 | I15: 5 | K15: 3 | L15: 3
A16: 501501017 | B16: 台東市 | C16: 臺東公園 | D16: 20 | E16: 3 | F16: 0 | H16: 3 | I16: 0 | K16: 3 | L16: 0
A17: 501501018 | B17: 台東市 | C17: 兒福聯盟臺東工作站 | D17: 27 | E17: 5 | F17: 7 | H17: 2 | I17: 7 | K17: 2 | L17: 7
A18: 501501019 | B18: 台東市 | C18: 國立臺東高級商業職業學校 | D18: 15 | E18: 4 | F18: 4 | H18: 3 | I18: 4 | J18: 10 | K18: 3 | L18: 4 | M18: 10
A19: 501501021 | B19: 台東市 | C19: 寶桑國小 | D19: 15 | E19: 3 | F19: 3 | H19: 3 | I19: 5 | K19: 3 | L19: 5
A20: 501501022 | B20: 台東市 | C20: 臺東縣環境保護局 | D20: 15 | E20: 4 | F20: 4 | H20: 2 | I20: 4 | K20: 2 | L20: 4
A21: 501501023 | B21: 台東市 | C21: 臺東市漢中街公園 | D21: 12 | E21: 3 | F21: 3 | H21: 2 | I21: 3 | K21: 2 | L21: 3
A22: 501501024 | B22: 台東市 | C22: 臺東聖母醫院 | D22: 18 | E22: 3 | F22: 3 | H22: 2 | I22: 3 | K22: 2 | L22: 3
A23: 501501025 | B23: 台東市 | C23: 柳州街停車場 | D23: 20 | E23: 2 | F23: 12 | H23: 2 | I23: 4 | K23: 2 | L23: 4
A24: 501501026 | B24: 台東市 | C24: 仁義北路河堤涼亭 | D24: 20 | E24: 4 | F24: 4 | H24: 2 | I24: 4 | K24: 2 | L24: 4
A25: 501501027 | B25: 台東市 | C25: 國立臺東高級中學學生宿舍 | D25: 20 | E25: 5 | F25: 5 | H25: 3 | I25: 5 | K25: 6 | L25: 5
A26: 501501029 | B26: 台東市 | C26: 桂林南路238巷與中華路一段719巷口 | D26: 18 | E26: 2 | F26: 4 | H26: 4 | I26: 4 | J26: 15 | K26: 4 | L26: 4 | M26: 15
A27: 501501030 | B27: 台東市 | C27: 臺東縣私立公東高級工業職業學校 | D27: 20 | E27: 4 | F27: 4 | H27: 4 | I27: 4 | K27: 4 | L27: 4
A28: 501501031 | B28: 台東市 | C28: 四維夜市 | D28: 17 | E28: 4 | F28: 4 | H28: 3 | I28: 3 | K28: 3 | L28: 3
A29: 501501032 | B29: 台東市 | C29: 四維路三段與傳廣路交叉口 | D29: 16 | E29: 4 | F29: 4 | H29: 2 | I29: 3 | K29: 2 | L29: 3
A30: 501501033 | B30: 台東市 | C30: 四維路三段與泰安街(西側) | D30: 20 | E30: 2 | F30: 3 | H30: 2 | I30: 3 | K30: 2 | L30: 3
A31: 501501034 | B31: 台東市 | C31: 開封街鐵馬道 | D31: 12 | E31: 3 | F31: 3 | H31: 3 | I31: 4 | K31: 3 | L31: 4
A32: 501501035 | B32: 台東市 | C32: 四維路三段與長安街交叉口 | D32: 13 | E32: 3 | F32: 3 | H32: 4 | I32: 3 | J32: 10 | K32: 4 | L32: 3 | M32: 10
A33: 501501036 | B33: 台東市 | C33: 臺東縣立新生國民中學 | D33: 23 | E33: 4 | F33: 4 | H33: 8 | I33: 7 | J33: 10 | K33: 8 | L33: 7 | M33: 10
A34: 501501037 | B34: 台東市 | C34: 臺東縣臺東市康樂國小 | D34: 20 | E34: 2 | F34: 4 | H34: 2 | I34: 4 | K34: 2 | L34: 4
A35: 501501038 | B35: 台東市 | C35: 臺東專科學校宿舍 | D35: 15 | E35: 2 | F35: 8 | G35: 8 | H35: 2 | I35: 8 | J35: 8 | K35: 2 | L35: 8 | M35: 8
A36: 501501039 | B36: 台東市 | C36: 臺東專科學校 | D36: 30 | E36: 2 | F36: 2 | H36: 1 | I36: 20 | J36: 10+10 | K36: 1 | L36: 20 | M36: 10+10
A37: 501501040 | B37: 台東市 | C37: 正氣公園 | D37: 16 | E37: 2 | F37: 3 | H37: 2 | I37: 3 | K37: 3 | L37: 3
A38: 501501041 | B38: 台東市 | C38: 長沙街溜冰場 | D38: 28 | E38: 7 | F38: 8 | H38: 5 | I38: 6 | K38: 4 | L38: 4
A39: 501501042 | B39: 台東市 | C39: 臺東航空站 | D39: 20 | E39: 5 | F39: 0 | H39: 5 | I39: 0 | K39: 5 | L39: 0
A40: 501501043 | B40: 台東市 | C40: 娜路彎大酒店 | D40: 30 | E40: 4 | F40: 7 | H40: 4 | I40: 5 | K40: 4 | L40: 5
...

Sheet 「D1假日」修訂版0217
A1: D1 | B1: 行政區 | C1: 場站名稱 | D1: 合約柱數 | E1: 夜班配置(假日) | G1: 2.0綁車 | H1: 早班配置(假日) | J1: 2.0綁車 | K1: 晚班配置(假日) | M1: 2.0綁車
A2: 501501001 | B2: 台東市 | C2: 臺東縣政府文化處圖書館 | D2: 55 | E2: 5 | F2: 20 | H2: 5 | I2: 20 | K2: 5 | L2: 20
A3: 501501002 | B3: 台東市 | C3: 臺東轉運站 | D3: 60 | E3: 5 | F3: 20 | H3: 5 | I3: 20 | K3: 5 | L3: 20
A4: 501501003 | B4: 台東市 | C4: 臺東市公所 | D4: 20 | E4: 3 | F4: 7 | H4: 3 | I4: 7 | K4: 3 | L4: 6
A5: 501501004 | B5: 台東市 | C5: 臺東縣政府 | D5: 25 | E5: 5 | F5: 7 | H5: 5 | I5: 7 | K5: 5 | L5: 7
A6: 501501006 | B6: 台東市 | C6: 微光市集 | D6: 30 | E6: 3 | F6: 7 | H6: 3 | I6: 7 | K6: 3 | L6: 7
A7: 501501008 | B7: 台東市 | C7: 臺東縣立體育場 | D7: 20 | E7: 3 | F7: 3 | H7: 3 | I7: 3 | K7: 3 | L7: 3
A8: 501501009 | B8: 台東市 | C8: 東海國宅 | D8: 17 | E8: 5 | F8: 5 | H8: 5 | I8: 4 | K8: 5 | L8: 4
A9: 501501010 | B9: 台東市 | C9: 東海運動公園 | D9: 15 | E9: 4 | F9: 4 | H9: 4 | I9: 3 | K9: 3 | L9: 3
A10: 501501011 | B10: 台東市 | C10: 臺東火車站 | D10: 50 | E10: 10 | F10: 25 | H10: 10 | I10: 25 | K10: 10 | L10: 20
A11: 501501012 | B11: 台東市 | C11: 臺東棒球村第一棒球場 | D11: 20 | E11: 4 | F11: 4 | H11: 5 | I11: 4 | K11: 5 | L11: 4
A12: 501501013 | B12: 台東市 | C12: 寶桑國中活動中心 | D12: 15 | E12: 4 | F12: 3 | H12: 4 | I12: 3 | K12: 5 | L12: 4
A13: 501501014 | B13: 台東市 | C13: 生日蛋糕公園 | D13: 18 | E13: 4 | F13: 2 | H13: 3 | I13: 2 | K13: 4 | L13: 2
... A43: 501501046 | B43: 台東市 | C43: 國立臺灣史前文化博物館 | D43: 30 | E43: 5 | F43: 5 | H43: 4 | I43: 5 | K43: 4 | L43: 5
A44: 501501047 | B44: 台東市 | C44: 臺東大學附屬體育高級中學 | D44: 20 | E44: 2 | F44: 13 | G44: 15 | H44: 2 | I44: 13 | J44: 15 | K44: 2 | L44: 13 | M44: 15
A45: 501501048 | B45: 台東市 | C45: 臺東表演藝術創生基地 | D45: 20 | E45: 5 | F45: 5 | H45: 5 | I45: 4 | K45: 3 | L45: 3
A46: 501501049 | B46: 台東市 | C46: 臺東市新生國民小學 | D46: 16 | E46: 3 | F46: 3 | H46: 3 | I46: 3 | K46: 3 | L46: 3
A47: 501501050 | B47: 台東市 | C47: 北町日式宿舍 | D47: 16 | E47: 3 | F47: 3 | H47: 3 | I47: 3 | K47: 4 | L47: 4
A48: 501501051 | B48: 台東市 | C48: 國立臺東大學知本校區正門 | D48: 30 | E48: 5 | F48: 5 | H48: 5 | I48: 4 | K48: 5 | L48: 5
A49: 501501052 | B49: 台東市 | C49: 卑南遺址公園 | D49: 31 | E49: 3 | F49: 3 | H49: 3 | I49: 3 | K49: 3 | L49: 3
A50: 501501053 | B50: 台東市 | C50: 新興路與北安路52巷口 | D50: 20 | E50: 6 | F50: 6 | H50: 4 | I50: 4 | K50: 4 | L50: 4
A51: 501501054 | B51: 台東市 | C51: 知本火車站 | D51: 30 | E51: 4 | F51: 9 | H51: 4 | I51: 8 | K51: 4 | L51: 8
A52: 501501055 | B52: 台東市 | C52: 臺東市仁愛國民小學 | D52: 25 | E52: 5 | F52: 7 | H52: 4 | I52: 7 | K52: 4 | L52: 7
A53: 501501056 | B53: 台東市 | C53: 南一街與南一街113巷口 | D53: 20 | E53: 4 | F53: 3 | H53: 4 | I53: 3 | K53: 4 | L53: 3
A54: 501501057 | B54: 台東市 | C54: 馬蘭部落更生聚會所 | D54: 18 | E54: 6 | F54: 0 | H54: 6 | I54: 0 | K54: 6 | L54: 0
A55: 501501058 | B55: 台東市 | C55: 統冠聯合超市(臺東店) | D55: 15 | E55: 3 | F55: 2 | H55: 3 | I55: 2 | K55: 3 | L55: 2
A56: 501501059 | B56: 台東市 | C56: 寶桑里活動中心 | D56: 22 | E56: 5 | F56: 4 | H56: 5 | I56: 4 | K56: 5 | L56: 4
... A81: 501501089 | B81: 台東市 | C81: 衡陽路151巷口 | D81: 19 | E81: 4 | F81: 4 | H81: 4 | I81: 4 | K81: 4 | L81: 4
A82: 501501090 | B82: 台東市 | C82: 原民創產園區 | D82: 19
A83: 501501091 | B83: 台東市 | C83: 復興路128號 | D83: 16 | E83: 3 | F83: 4 | H83: 3 | I83: 3 | K83: 3 | L83: 3
A84: 501502001 | B84: 卑南鄉 | C84: 卑南遊客中心 | D84: 16 | E84: 4 | F84: 2 | H84: 4 | I84: 2 | K84: 4 | L84: 2
A85: 501502002 | B85: 卑南鄉 | C85: 臺東戶政事務所卑南辦公室 | D85: 17 | E85: 5 | F85: 0 | H85: 5 | I85: 0 | K85: 5 | L85: 0
A86: 501502004 | B86: 卑南鄉 | C86: 7-11東遊季門市 | D86: 20 | E86: 5 | F86: 6 | H86: 5 | I86: 6 | K86: 5 | L86: 6
A87: 501502006 | B87: 卑南鄉 | C87: 知本第一公有停車場 | D87: 28 | E87: 3 | F87: 5 | H87: 3 | I87: 5 | K87: 3 | L87: 5
A88: 501502007 | B88: 卑南鄉 | C88: 東台溫泉飯店 | D88: 24 | E88: 6 | F88: 5 | H88: 6 | I88: 5 | K88: 6 | L88: 5
A89: 501502008 | B89: 卑南鄉 | C89: 知本國家森林遊樂區 | D89: 24 | E89: 4 | F89: 4 | H89: 4 | I89: 4 | K89: 4 | L89: 4
D90: =SUM(D2:D89) -> 1921 | E90: =SUM(E2:E89) -> 335 | F90: =SUM(F2:F89) -> 444 | G90: =SUM(G2:G89) -> 15 | H90: =SUM(H2:H89) -> 328 | I90: =SUM(I2:I89) -> 426 | J90: =SUM(J2:J89) -> 15 | K90: =SUM(K2:K89) -> 333 | ... M90: =SUM(M2:M89) -> 15

Sheet 「D1假日」0307
A1: D1 | B1: 行政區 | C1: 場站名稱 | D1: 合約柱數 | E1: 夜班配置(假日) | G1: 2.0綁車 | H1: 早班配置(假日) | J1: 2.0綁車 | K1: 晚班配置(假日) | M1: 2.0綁車
A2: 501501001 | B2: 台東市 | C2: 臺東縣政府文化處圖書館 | D2: 55 | E2: 10 | F2: 15 | H2: 8 | I2: 8 | K2: 5 | L2: 5
A3: 501501002 | B3: 台東市 | C3: 臺東轉運站 | D3: 60 | E3: 5 | F3: 20 | H3: 5 | I3: 15 | K3: 5 | L3: 10
A4: 501501003 | B4: 台東市 | C4: 臺東市公所 | D4: 20 | E4: 3 | F4: 7 | H4: 3 | I4: 6 | K4: 3 | L4: 6
A5: 501501004 | B5: 台東市 | C5: 臺東縣政府 | D5: 25 | E5: 5 | F5: 7 | H5: 5 | I5: 6 | K5: 5 | L5: 7
A6: 501501006 | B6: 台東市 | C6: 微光市集 | D6: 30 | E6: 3 | F6: 7 | H6: 3 | I6: 7 | K6: 3 | L6: 7
A7: 501501008 | B7: 台東市 | C7: 臺東縣立體育場 | D7: 20 | E7: 3 | F7: 3 | H7: 3 | I7: 3 | K7: 3 | L7: 3
A8: 501501009 | B8: 台東市 | C8: 東海國宅 | D8: 17 | E8: 3 | F8: 4 | H8: 4 | I8: 4 | K8: 3 | L8: 3
A9: 501501010 | B9: 台東市 | C9: 東海運動公園 | D9: 15 | E9: 2 | F9: 3 | H9: 4 | I9: 3 | K9: 3 | L9: 3
A10: 501501011 | B10: 台東市 | C10: 臺東火車站 | D10: 50 | E10: 10 | F10: 20 | H10: 5 | I10: 20 | K10: 5 | L10: 15
A11: 501501012 | B11: 台東市 | C11: 臺東棒球村第一棒球場 | D11: 20 | E11: 4 | F11: 4 | H11: 5 | I11: 4 | K11: 4 | L11: 3
A12: 501501013 | B12: 台東市 | C12: 寶桑國中活動中心 | D12: 15 | E12: 3 | F12: 2 | H12: 4 | I12: 3 | K12: 6 | L12: 3
A13: 501501014 | B13: 台東市 | C13: 生日蛋糕公園 | D13: 18 | E13: 3 | F13: 3 | H13: 4 | I13: 2 | K13: 4 | L13: 2
... A43: 501501046 | B43: 台東市 | C43: 國立臺灣史前文化博物館 | D43: 30 | E43: 5 | F43: 4 | H43: 4 | I43: 5 | K43: 3 | L43: 3
A44: 501501047 | B44: 台東市 | C44: 臺東大學附屬體育高級中學 | D44: 20 | E44: 2 | F44: 12 | G44: 15 | H44: 2 | I44: 12 | J44: 12 | K44: 2 | L44: 12 | M44: 12
A45: 501501048 | B45: 台東市 | C45: 臺東表演藝術創生基地 | D45: 20 | E45: 5 | F45: 3 | H45: 5 | I45: 3 | K45: 3 | L45: 3
A46: 501501049 | B46: 台東市 | C46: 臺東市新生國民小學 | D46: 16 | E46: 3 | F46: 2 | H46: 3 | I46: 2 | K46: 3 | L46: 2
A47: 501501050 | B47: 台東市 | C47: 北町日式宿舍 | D47: 16 | E47: 3 | F47: 3 | H47: 3 | I47: 3 | K47: 3 | L47: 3
A48: 501501051 | B48: 台東市 | C48: 國立臺東大學知本校區正門 | D48: 30 | E48: 5 | F48: 5 | H48: 5 | I48: 4 | K48: 3 | L48: 3
A49: 501501052 | B49: 台東市 | C49: 卑南遺址公園 | D49: 31 | E49: 3 | F49: 3 | H49: 3 | I49: 3 | K49: 3 | L49: 3
A50: 501501053 | B50: 台東市 | C50: 新興路與北安路52巷口 | D50: 20 | E50: 5 | F50: 5 | H50: 4 | I50: 4 | K50: 4 | L50: 4
A51: 501501054 | B51: 台東市 | C51: 知本火車站 | D51: 30 | E51: 4 | F51: 9 | H51: 4 | I51: 8 | K51: 4 | L51: 8
A52: 501501055 | B52: 台東市 | C52: 臺東市仁愛國民小學 | D52: 25 | E52: 5 | F52: 5 | H52: 4 | I52: 6 | K52: 4 | L52: 6
A53: 501501056 | B53: 台東市 | C53: 南一街與南一街113巷口 | D53: 20 | E53: 3 | F53: 3 | H53: 3 | I53: 3 | K53: 3 | L53: 3
A54: 501501057 | B54: 台東市 | C54: 馬蘭部落更生聚會所 | D54: 18 | E54: 3 | F54: 0 | H54: 3 | I54: 0 | K54: 3 | L54: 0
A55: 501501058 | B55: 台東市 | C55: 統冠聯合超市(臺東店) | D55: 15 | E55: 3 | F55: 2 | H55: 3 | I55: 2 | K55: 3 | L55: 2
A56: 501501059 | B56: 台東市 | C56: 寶桑里活動中心 | D56: 22 | E56: 5 | F56: 4 | H56: 5 | I56: 4 | K56: 4 | L56: 4
... A89: 501502008 | B89: 卑南鄉 | C89: 知本國家森林遊樂區 | D89: 24 | E89: 4 | F89: 4 | H89: 4 | I89: 4 | K89: 4 | L89: 4
D90: =SUM(D2:D89) -> 1921 | E90: =SUM(E2:E89) -> 309 | F90: =SUM(F2:F89) -> 391 | G90: =SUM(G2:G89) -> 15 | H90: =SUM(H2:H89) -> 298 | I90: =SUM(I2:I89) -> 364 | J90: =SUM(J2:J89) -> 12 | K90: =SUM(K2:K89) -> 287 | ... M90: =SUM(M2:M89) -> 12

Sheet 「D2 D3平日」修訂版217
A1: D2 | B1: 行政區 | C1: 場站名稱 | D1: 合約柱數 | E1: 夜班配置(平日) | G1: 2.0綁車 | H1: 早班配置(平日) | J1: 2.0綁車 | K1: 晚班配置(平日) | M1: 2.0綁車
A2: 501502003 | B2: 卑南鄉 | C2: 卑南鄉老人文康中心 | D2: 15 | E2: 4 | F2: 0 | H2: 4 | I2: 0 | K2: 4 | L2: 0
A3: 501503001 | B3: 鹿野鄉 | C3: 瑞源車站 | D3: 20 | E3: 5 | F3: 0 | H3: 5 | I3: 0 | K3: 5 | L3: 0
A4: 501503002 | B4: 鹿野鄉 | C4: 永安農產品銷售中心 | D4: 23 | E4: 4 | F4: 0 | H4: 4 | I4: 0 | K4: 4 | L4: 0
A5: 501503003 | B5: 鹿野鄉 | C5: 龍田大草坪 | D5: 30 | E5: 4 | F5: 4 | H5: 4 | I5: 4 | K5: 4 | L5: 4
A6: 501503004 | B6: 鹿野鄉 | C6: 鹿野車站 | D6: 49 | E6: 2 | F6: 8 | H6: 2 | I6: 8 | K6: 2 | L6: 8
A7: 501503005 | B7: 鹿野鄉 | C7: 福鹿山休閒農莊 | D7: 22 | E7: 4 | F7: 5 | H7: 4 | I7: 5 | K7: 4 | L7: 5
A8: 501503006 | B8: 鹿野鄉 | C8: 鹿野地區農會 | D8: 24 | E8: 4 | F8: 0 | H8: 4 | I8: 0 | K8: 4 | L8: 0
A9: 501503007 | B9: 鹿野鄉 | C9: 龍田老人會館 | D9: 20 | E9: 1 | F9: 4 | H9: 1 | I9: 4 | K9: 1 | L9: 4
A10: 501503008 | B10: 鹿野鄉 | C10: 永安環教中心 | D10: 20 | E10: 4 | F10: 0 | H10: 4 | I10: 0 | K10: 4 | L10: 0
A11: 501504001 | B11: 關山鎮 | C11: 關山車站 | D11: 60 | E11: 4 | F11: 22 | H11: 4 | I11: 22 | K11: 4 | L11: 22
A12: 501504003 | B12: 關山鎮 | C12: 米國學校 | D12: 20 | E12: 2 | F12: 6 | H12: 2 | I12: 6 | K12: 2 | L12: 6
A13: 501504004 | B13: 關山鎮 | C13: 關山工商 | D13: 30 | E13: 4 | F13: 6 | H13: 4 | I13: 10 | K13: 4 | L13: 10
... A23: 501505007 | B23: 池上鄉 | C23: 日暉國際渡假村 | D23: 30 | E23: 7 | F23: 5 | H23: 7 | I23: 5 | K23: 7 | L23: 5
D65: =SUM(D2:D64) -> 631 | E65: =SUM(E2:E64) -> 106 | F65: =SUM(F2:F64) -> 97 | G65: =SUM(G2:G64) -> 0 | H65: =SUM(H2:H64) -> 106 | I65: =SUM(I2:I64) -> 107 | J65: =SUM(J2:J64) -> 0 | K65: =SUM(K2:K64) -> 104 | ... M65: =SUM(M2:M64) -> 0
A68: D3 | B68: 行政區 | C68: 場站名稱 | D68: 合約柱數 | E68: 夜班配置(平日) | G68: 2.0綁車 | H68: 早班配置(平日) | J68: 2.0綁車 | K68: 晚班配置(平日) | M68: 2.0綁車
A69: 501502005 | B69: 卑南鄉 | C69: 富山護漁區 | D69: 15 | E69: 4 | F69: 0 | H69: 4 | I69: 0 | K69: 4 | L69: 0
A70: 501506001 | B70: 成功鎮 | C70: 成功漁港 | D70: 15 | E70: 7 | F70: 0 | H70: 7 | I70: 0 | K70: 7 | L70: 0
A71: 501506002 | B71: 成功鎮 | C71: 成功鎮公所 | D71: 20 | E71: 4 | F71: 3 | H71: 4 | I71: 3 | K71: 4 | L71: 3
A72: 501506003 | B72: 成功鎮 | C72: 成功豆花 | D72: 20 | E72: 4 | F72: 3 | H72: 4 | I72: 3 | K72: 4 | L72: 3
A73: 501506005 | B73: 成功鎮 | C73: 東管處停車場 | D73: 24 | E73: 5 | F73: 0 | H73: 5 | I73: 0 | K73: 5 | L73: 0
A74: 501506006 | B74: 成功鎮 | C74: 三仙台 | D74: 30 | E74: 7 | F74: 0 | H74: 7 | I74: 0 | K74: 7 | L74: 0
A75: 501506007 | B75: 成功鎮 | C75: 成功海濱公園 | D75: 30 | E75: 4 | F75: 5 | H75: 4 | I75: 5 | K75: 4 | L75: 5
A76: 501509001 | B76: 東河鄉 | C76: 都蘭舊糖廠 | D76: 28 | E76: 4 | F76: 4 | H76: 4 | I76: 4 | K76: 4 | L76: 4
A77: 501509002 | B77: 東河鄉 | C77: 東河消防隊 | D77: 20 | E77: 4 | F77: 0 | H77: 4 | I77: 0 | K77: 4 | L77: 0
A78: 501506004 | B78: 成功鎮 | C78: 成功消防隊 | D78: 28 | E78: 4 | F78: 2 | H78: 4 | I78: 2 | K78: 4 | L78: 2
D79: =SUM(D69:D77) -> 202 | E79: =SUM(E69:E78) -> 47 | F79: =SUM(F69:F78) -> 17 | G79: =SUM(G69:G77) -> 0 | H79: =SUM(H69:H78) -> 47 | I79: =SUM(I69:I78) -> 17 | J79: =SUM(J69:J77) -> 0 | K79: =SUM(K69:K78) -> 47 | L79: =SUM(L69:L78) -> 17 | M79: =SUM(M69:M77) -> 0

Sheet 「D2 D3假日」修訂版217
A1: D2 | B1: 行政區 | C1: 場站名稱 | D1: 合約柱數 | E1: 夜班配置(假日) | G1: 2.0綁車 | H1: 早班配置(假日) | J1: 2.0綁車 | K1: 晚班配置(假日) | M1: 2.0綁車
A2: 501502003 | B2: 卑南鄉 | C2: 卑南鄉老人文康中心 | D2: 15 | E2: 4 | F2: 0 | H2: 4 | I2: 0 | K2: 4 | L2: 0
A3: 501503001 | B3: 鹿野鄉 | C3: 瑞源車站 | D3: 20 | E3: 5 | F3: 0 | H3: 4 | I3: 0 | K3: 4 | L3: 0
A4: 501503002 | B4: 鹿野鄉 | C4: 永安農產品銷售中心 | D4: 23 | E4: 4 | F4: 0 | H4: 4 | I4: 0 | K4: 4 | L4: 0
A5: 501503003 | B5: 鹿野鄉 | C5: 龍田大草坪 | D5: 30 | E5: 8 | F5: 0 | H5: 8 | I5: 0 | K5: 8 | L5: 0
A6: 501503004 | B6: 鹿野鄉 | C6: 鹿野車站 | D6: 49 | E6: 12 | F6: 8 | H6: 12 | I6: 8 | K6: 5 | L6: 8
A7: 501503005 | B7: 鹿野鄉 | C7: 福鹿山休閒農莊 | D7: 22 | E7: 4 | F7: 5 | H7: 4 | I7: 5 | K7: 4 | L7: 5
A8: 501503006 | B8: 鹿野鄉 | C8: 鹿野地區農會 | D8: 24 | E8: 2 | F8: 0 | H8: 2 | I8: 0 | K8: 2 | L8: 0
A9: 501503007 | B9: 鹿野鄉 | C9: 龍田老人會館 | D9: 20 | E9: 2 | F9: 5 | H9: 2 | I9: 5 | K9: 2 | L9: 5
A10: 501503008 | B10: 鹿野鄉 | C10: 永安環教中心 | D10: 20 | E10: 2 | F10: 0 | H10: 2 | I10: 0 | K10: 2 | L10: 0
A11: 501504001 | B11: 關山鎮 | C11: 關山車站 | D11: 60 | E11: 10 | F11: 21 | H11: 10 | I11: 21 | K11: 10 | L11: 15
A12: 501504003 | B12: 關山鎮 | C12: 米國學校 | D12: 20 | E12: 3 | F12: 2 | H12: 3 | I12: 2 | K12: 2 | L12: 2
A13: 501504004 | B13: 關山鎮 | C13: 關山工商 | D13: 30 | E13: 4 | F13: 2 | H13: 4 | I13: 2 | K13: 5 | L13: 2
... A23: 501505007 | B23: 池上鄉 | C23: 日暉國際渡假村 | D23: 30 | E23: 13 | F23: 4 | H23: 13 | I23: 4 | K23: 13 | L23: 4
D65: =SUM(D2:D64) -> 631 | E65: =SUM(E2:E64) -> 144 | F65: =SUM(F2:F64) -> 78 | G65: =SUM(G2:G64) -> 0 | H65: =SUM(H2:H64) -> 142 | I65: =SUM(I2:I64) -> 78 | J65: =SUM(J2:J64) -> 0 | K65: =SUM(K2:K64) -> 137 | ... M65: =SUM(M2:M64) -> 0
A68: D3 | B68: 行政區 | C68: 場站名稱 | D68: 合約柱數 | E68: 夜班配置(假日) | G68: 2.0綁車 | H68: 早班配置(假日) | J68: 2.0綁車 | K68: 晚班配置(假日) | M68: 2.0綁車
A69: 501502005 | B69: 卑南鄉 | C69: 富山護漁區 | D69: 15 | E69: 4 | F69: 0 | H69: 4 | I69: 0 | K69: 4 | L69: 0
A70: 501506001 | B70: 成功鎮 | C70: 成功漁港 | D70: 15 | E70: 8 | F70: 0 | H70: 8 | I70: 0 | K70: 8 | L70: 0
A71: 501506002 | B71: 成功鎮 | C71: 成功鎮公所 | D71: 20 | E71: 4 | F71: 3 | H71: 5 | I71: 3 | K71: 5 | L71: 3
A72: 501506003 | B72: 成功鎮 | C72: 成功豆花 | D72: 20 | E72: 4 | F72: 3 | H72: 5 | I72: 3 | K72: 5 | L72: 3
A73: 501506005 | B73: 成功鎮 | C73: 東管處停車場 | D73: 24 | E73: 6 | F73: 0 | H73: 6 | I73: 0 | K73: 6 | L73: 0
A74: 501506006 | B74: 成功鎮 | C74: 三仙台 | D74: 30 | E74: 10 | F74: 0 | H74: 10 | I74: 0 | K74: 10 | L74: 0
A75: 501506007 | B75: 成功鎮 | C75: 成功海濱公園 | D75: 30 | E75: 4 | F75: 5 | H75: 4 | I75: 5 | K75: 4 | L75: 5
A76: 501509001 | B76: 東河鄉 | C76: 都蘭舊糖廠 | D76: 28 | E76: 6 | F76: 4 | H76: 6 | I76: 4 | K76: 6 | L76: 4
A77: 501509002 | B77: 東河鄉 | C77: 東河消防隊 | D77: 20 | E77: 4 | F77: 0 | H77: 4 | I77: 0 | K77: 4 | L77: 0
A78: 501506004 | B78: 成功鎮 | C78: 成功消防隊 | D78: 28 | E78: 4 | F78: 2 | H78: 4 | I78: 2 | K78: 4 | L78: 2
D79: =SUM(D69:D78) -> 230 | E79: =SUM(E69:E78) -> 54 | F79: =SUM(F69:F78) -> 17 | G79: =SUM(G69:G77) -> 0 | H79: =SUM(H69:H78) -> 56 | I79: =SUM(I69:I78) -> 17 | J79: =SUM(J69:J77) -> 0 | K79: =SUM(K69:K78) -> 56 | L79: =SUM(L69:L78) -> 17 | M79: =SUM(M69:M77) -> 0

Sheet 「D2 D3平日」修訂版224
A1: D2 | B1: 行政區 | C1: 場站名稱 | D1: 合約柱數 | E1: 夜班配置(平日) | G1: 2.0綁車 | H1: 早班配置(平日) | J1: 2.0綁車 | K1: 晚班配置(平日) | M1: 2.0綁車
A2: 501502003 | B2: 卑南鄉 | C2: 卑南鄉老人文康中心 | D2: 15 | E2: 4 | F2: 0 | H2: 4 | I2: 0 | K2: 4 | L2: 0
A3: 501503001 | B3: 鹿野鄉 | C3: 瑞源車站 | D3: 20 | E3: 5 | F3: 0 | H3: 4 | I3: 0 | K3: 4 | L3: 0
A4: 501503002 | B4: 鹿野鄉 | C4: 永安農產品銷售中心 | D4: 23 | E4: 4 | F4: 0 | H4: 4 | I4: 0 | K4: 4 | L4: 0
A5: 501503003 | B5: 鹿野鄉 | C5: 龍田大草坪 | D5: 30 | E5: 5 | F5: 0 | H5: 4 | I5: 0 | K5: 4 | L5: 0
A6: 501503004 | B6: 鹿野鄉 | C6: 鹿野車站 | D6: 49 | E6: 2 | F6: 8 | H6: 2 | I6: 6 | K6: 2 | L6: 6
A7: 501503005 | B7: 鹿野鄉 | C7: 福鹿山休閒農莊 | D7: 22 | E7: 4 | F7: 5 | H7: 4 | I7: 3 | K7: 4 | L7: 3
A8: 501503006 | B8: 鹿野鄉 | C8: 鹿野地區農會 | D8: 24 | E8: 4 | F8: 0 | H8: 4 | I8: 0 | K8: 4 | L8: 0
A9: 501503007 | B9: 鹿野鄉 | C9: 龍田老人會館 | D9: 20 | E9: 5 | F9: 0 | H9: 4 | I9: 0 | K9: 4 | L9: 0
A10: 501503008 | B10: 鹿野鄉 | C10: 永安環教中心 | D10: 20 | E10: 4 | F10: 0 | H10: 4 | I10: 0 | K10: 4 | L10: 0
A11: 501504001 | B11: 關山鎮 | C11: 關山車站 | D11: 60 | E11: 4 | F11: 22 | H11: 4 | I11: 18 | K11: 4 | L11: 16
A12: 501504003 | B12: 關山鎮 | C12: 米國學校 | D12: 20 | E12: 2 | F12: 6 | H12: 2 | I12: 4 | K12: 2 | L12: 4
A13: 501504004 | B13: 關山鎮 | C13: 關山工商 | D13: 30 | E13: 2 | F13: 6 | H13: 2 | I13: 8 | K13: 2 | L13: 10
... A23: 501505007 | B23: 池上鄉 | C23: 日暉國際渡假村 | D23: 30 | E23: 6 | F23: 5 | H23: 6 | I23: 4 | K23: 6 | L23: 4
D65: =SUM(D2:D64) -> 631 | E65: =SUM(E2:E64) -> 121 | F65: =SUM(F2:F64) -> 92 | G65: =SUM(G2:G64) -> 0 | H65: =SUM(H2:H64) -> 109 | I65: =SUM(I2:I64) -> 75 | J65: =SUM(J2:J64) -> 0 | K65: =SUM(K2:K64) -> 106 | ... M65: =SUM(M2:M64) -> 0
A68: D3 | B68: 行政區 | C68: 場站名稱 | D68: 合約柱數 | E68: 夜班配置(平日) | G68: 2.0綁車 | H68: 早班配置(平日) | J68: 2.0綁車 | K68: 晚班配置(平日) | M68: 2.0綁車
A69: 501502005 | B69: 卑南鄉 | C69: 富山護漁區 | D69: 15 | E69: 4 | F69: 0 | H69: 4 | I69: 0 | K69: 4 | L69: 0
A70: 501506001 | B70: 成功鎮 | C70: 成功漁港 | D70: 15 | E70: 7 | F70: 0 | H70: 7 | I70: 0 | K70: 7 | L70: 0
A71: 501506002 | B71: 成功鎮 | C71: 成功鎮公所 | D71: 20 | E71: 4 | F71: 3 | H71: 4 | I71: 3 | K71: 4 | L71: 3
A72: 501506003 | B72: 成功鎮 | C72: 成功豆花 | D72: 20 | E72: 4 | F72: 3 | H72: 4 | I72: 3 | K72: 4 | L72: 3
A73: 501506005 | B73: 成功鎮 | C73: 東管處停車場 | D73: 24 | E73: 5 | F73: 0 | H73: 5 | I73: 0 | K73: 5 | L73: 0
A74: 501506006 | B74: 成功鎮 | C74: 三仙台 | D74: 30 | E74: 7 | F74: 0 | H74: 7 | I74: 0 | K74: 7 | L74: 0
A75: 501506007 | B75: 成功鎮 | C75: 成功海濱公園 | D75: 30 | E75: 4 | F75: 5 | H75: 4 | I75: 5 | K75: 4 | L75: 5
A76: 501509001 | B76: 東河鄉 | C76: 都蘭舊糖廠 | D76: 28 | E76: 4 | F76: 4 | H76: 4 | I76: 4 | K76: 4 | L76: 4
A77: 501509002 | B77: 東河鄉 | C77: 東河消防隊 | D77: 20 | E77: 4 | F77: 0 | H77: 4 | I77: 0 | K77: 4 | L77: 0
A78: 501506004 | B78: 成功鎮 | C78: 成功消防隊 | D78: 28 | E78: 4 | F78: 2 | H78: 4 | I78: 2 | K78: 4 | L78: 2
D79: =SUM(D69:D77) -> 202 | E79: =SUM(E69:E78) -> 47 | F79: =SUM(F69:F78) -> 17 | G79: =SUM(G69:G77) -> 0 | H79: =SUM(H69:H78) -> 47 | I79: =SUM(I69:I78) -> 17 | J79: =SUM(J69:J77) -> 0 | K79: =SUM(K69:K78) -> 47 | L79: =SUM(L69:L78) -> 17 | M79: =SUM(M69:M77) -> 0

Sheet 「D2 D3假日」修訂版224
A1: D2 | B1: 行政區 | C1: 場站名稱 | D1: 合約柱數 | E1: 夜班配置(假日) | G1: 2.0綁車 | H1: 早班配置(假日) | J1: 2.0綁車 | K1: 晚班配置(假日) | M1: 2.0綁車
A2: 501502003 | B2: 卑南鄉 | C2: 卑南鄉老人文康中心 | D2: 15 | E2: 4 | F2: 0 | H2: 4 | I2: 0 | K2: 4 | L2: 0
A3: 501503001 | B3: 鹿野鄉 | C3: 瑞源車站 | D3: 20 | E3: 5 | F3: 0 | H3: 4 | I3: 0 | K3: 4 | L3: 0
A4: 501503002 | B4: 鹿野鄉 | C4: 永安農產品銷售中心 | D4: 23 | E4: 4 | F4: 0 | H4: 4 | I4: 0 | K4: 4 | L4: 0
A5: 501503003 | B5: 鹿野鄉 | C5: 龍田大草坪 | D5: 30 | E5: 5 | F5: 0 | H5: 4 | I5: 0 | K5: 4 | L5: 0
A6: 501503004 | B6: 鹿野鄉 | C6: 鹿野車站 | D6: 49 | E6: 2 | F6: 8 | H6: 2 | I6: 6 | K6: 2 | L6: 6
A7: 501503005 | B7: 鹿野鄉 | C7: 福鹿山休閒農莊 | D7: 22 | E7: 4 | F7: 5 | H7: 4 | I7: 3 | K7: 4 | L7: 3
A8: 501503006 | B8: 鹿野鄉 | C8: 鹿野地區農會 | D8: 24 | E8: 4 | F8: 0 | H8: 4 | I8: 0 | K8: 4 | L8: 0
A9: 501503007 | B9: 鹿野鄉 | C9: 龍田老人會館 | D9: 20 | E9: 5 | F9: 0 | H9: 4 | I9: 0 | K9: 4 | L9: 0
A10: 501503008 | B10: 鹿野鄉 | C10: 永安環教中心 | D10: 20 | E10: 4 | F10: 0 | H10: 4 | I10: 0 | K10: 4 | L10: 0
A11: 501504001 | B11: 關山鎮 | C11: 關山車站 | D11: 60 | E11: 4 | F11: 17 | H11: 3 | I11: 11 | K11: 3 | L11: 12
A12: 501504003 | B12: 關山鎮 | C12: 米國學校 | D12: 20 | E12: 2 | F12: 6 | H12: 2 | I12: 5 | K12: 2 | L12: 4
A13: 501504004 | B13: 關山鎮 | C13: 關山工商 | D13: 30 | E13: 2 | F13: 6 | H13: 2 | I13: 3 | K13: 2 | L13: 4
... A23: 501505007 | B23: 池上鄉 | C23: 日暉國際渡假村 | D23: 30 | E23: 6 | F23: 5 | H23: 4 | I23: 4 | K23: 4 | L23: 4
D65: =SUM(D2:D64) -> 631 | E65: =SUM(E2:E64) -> 121 | F65: =SUM(F2:F64) -> 92 | G65: =SUM(G2:G64) -> 0 | H65: =SUM(H2:H64) -> 96 | I65: =SUM(I2:I64) -> 63 | J65: =SUM(J2:J64) -> 0 | K65: =SUM(K2:K64) -> 95 | ... M65: =SUM(M2:M64) -> 0
A68: D3 | B68: 行政區 | C68: 場站名稱 | D68: 合約柱數 | E68: 夜班配置(假日) | G68: 2.0綁車 | H68: 早班配置(假日) | J68: 2.0綁車 | K68: 晚班配置(假日) | M68: 2.0綁車
A69: 501502005 | B69: 卑南鄉 | C69: 富山護漁區 | D69: 15 | E69: 4 | F69: 0 | H69: 4 | I69: 0 | K69: 4 | L69: 0
A70: 501506001 | B70: 成功鎮 | C70: 成功漁港 | D70: 15 | E70: 8 | F70: 0 | H70: 8 | I70: 0 | K70: 8 | L70: 0
A71: 501506002 | B71: 成功鎮 | C71: 成功鎮公所 | D71: 20 | E71: 4 | F71: 3 | H71: 5 | I71: 3 | K71: 5 | L71: 3
A72: 501506003 | B72: 成功鎮 | C72: 成功豆花 | D72: 20 | E72: 4 | F72: 3 | H72: 5 | I72: 3 | K72: 5 | L72: 3
A73: 501506005 | B73: 成功鎮 | C73: 東管處停車場 | D73: 24 | E73: 6 | F73: 0 | H73: 6 | I73: 0 | K73: 6 | L73: 0
A74: 501506006 | B74: 成功鎮 | C74: 三仙台 | D74: 30 | E74: 10 | F74: 0 | H74: 10 | I74: 0 | K74: 10 | L74: 0
A75: 501506007 | B75: 成功鎮 | C75: 成功海濱公園 | D75: 30 | E75: 4 | F75: 5 | H75: 4 | I75: 5 | K75: 4 | L75: 5
A76: 501509001 | B76: 東河鄉 | C76: 都蘭舊糖廠 | D76: 28 | E76: 6 | F76: 4 | H76: 6 | I76: 4 | K76: 6 | L76: 4
A77: 501509002 | B77: 東河鄉 | C77: 東河消防隊 | D77: 20 | E77: 4 | F77: 0 | H77: 4 | I77: 0 | K77: 4 | L77: 0
A78: 501506004 | B78: 成功鎮 | C78: 成功消防隊 | D78: 28 | E78: 4 | F78: 2 | H78: 4 | I78: 2 | K78: 4 | L78: 2
D79: =SUM(D69:D78) -> 230 | E79: =SUM(E69:E78) -> 54 | F79: =SUM(F69:F78) -> 17 | G79: =SUM(G69:G77) -> 0 | H79: =SUM(H69:H78) -> 56 | I79: =SUM(I69:I78) -> 17 | J79: =SUM(J69:J77) -> 0 | K79: =SUM(K69:K78) -> 56 | L79: =SUM(L69:L78) -> 17 | M79: =SUM(M69:M77) -> 0

Sheet 「D2 D3假日」修訂版0307
A1: D2 | B1: 行政區 | C1: 場站名稱 | D1: 合約柱數 | E1: 夜班配置(假日) | G1: 2.0綁車 | H1: 早班配置(假日) | J1: 2.0綁車 | K1: 晚班配置(假日) | M1: 2.0綁車
A2: 501502003 | B2: 卑南鄉 | C2: 卑南鄉老人文康中心 | D2: 15 | E2: 3 | F2: 0 | H2: 3 | I2: 0 | K2: 3 | L2: 0
A3: 501503001 | B3: 鹿野鄉 | C3: 瑞源車站 | D3: 20 | E3: 4 | F3: 0 | H3: 4 | I3: 0 | K3: 4 | L3: 0
A4: 501503002 | B4: 鹿野鄉 | C4: 永安農產品銷售中心 | D4: 23 | E4: 4 | F4: 0 | H4: 4 | I4: 0 | K4: 4 | L4: 0
A5: 501503003 | B5: 鹿野鄉 | C5: 龍田大草坪 | D5: 30 | E5: 5 | F5: 4 | H5: 4 | I5: 0 | K5: 4 | L5: 0
A6: 501503004 | B6: 鹿野鄉 | C6: 鹿野車站 | D6: 49 | E6: 2 | F6: 8 | H6: 2 | I6: 6 | K6: 2 | L6: 6
A7: 501503005 | B7: 鹿野鄉 | C7: 福鹿山休閒農莊 | D7: 22 | E7: 4 | F7: 5 | H7: 4 | I7: 3 | K7: 4 | L7: 3
A8: 501503006 | B8: 鹿野鄉 | C8: 鹿野地區農會 | D8: 24 | E8: 4 | F8: 0 | H8: 4 | I8: 0 | K8: 4 | L8: 0
A9: 501503007 | B9: 鹿野鄉 | C9: 龍田老人會館 | D9: 20 | E9: 5 | F9: 5 | H9: 4 | I9: 0 | K9: 4 | L9: 0
A10: 501503008 | B10: 鹿野鄉 | C10: 永安環教中心 | D10: 20 | E10: 4 | F10: 0 | H10: 4 | I10: 0 | K10: 4 | L10: 0
A11: 501504001 | B11: 關山鎮 | C11: 關山車站 | D11: 60 | E11: 8 | F11: 15 | H11: 4 | I11: 10 | K11: 8 | L11: 10
A12: 501504003 | B12: 關山鎮 | C12: 米國學校 | D12: 20 | E12: 2 | F12: 4 | H12: 2 | I12: 4 | K12: 2 | L12: 4
A13: 501504004 | B13: 關山鎮 | C13: 關山工商 | D13: 30 | E13: 2 | F13: 6 | H13: 2 | I13: 6 | K13: 2 | L13: 6
... A23: 501505007 | B23: 池上鄉 | C23: 日暉國際渡假村 | D23: 30 | E23: 14 | F23: 7 | H23: 6 | I23: 4 | K23: 6 | L23: 4
D65: =SUM(D2:D64) -> 631 | E65: =SUM(E2:E64) -> 166 | F65: =SUM(F2:F64) -> 121 | G65: =SUM(G2:G64) -> 0 | H65: =SUM(H2:H64) -> 99 | I65: =SUM(I2:I64) -> 72 | J65: =SUM(J2:J64) -> 0 | K65: =SUM(K2:K64) -> 103 | ... M65: =SUM(M2:M64) -> 0
A68: D3 | B68: 行政區 | C68: 場站名稱 | D68: 合約柱數 | E68: 夜班配置(假日) | G68: 2.0綁車 | H68: 早班配置(假日) | J68: 2.0綁車 | K68: 晚班配置(假日) | M68: 2.0綁車
A69: 501502005 | B69: 卑南鄉 | C69: 富山護漁區 | D69: 15 | E69: 3 | F69: 0 | H69: 3 | I69: 0 | K69: 3 | L69: 0
A70: 501506001 | B70: 成功鎮 | C70: 成功漁港 | D70: 15 | E70: 8 | F70: 0 | H70: 8 | I70: 0 | K70: 8 | L70: 0
A71: 501506002 | B71: 成功鎮 | C71: 成功鎮公所 | D71: 20 | E71: 4 | F71: 3 | H71: 5 | I71: 3 | K71: 5 | L71: 3
A72: 501506003 | B72: 成功鎮 | C72: 成功豆花 | D72: 20 | E72: 4 | F72: 3 | H72: 5 | I72: 3 | K72: 5 | L72: 3
A73: 501506005 | B73: 成功鎮 | C73: 東管處停車場 | D73: 24 | E73: 3 | F73: 0 | H73: 3 | I73: 0 | K73: 3 | L73: 0
A74: 501506006 | B74: 成功鎮 | C74: 三仙台 | D74: 30 | E74: 10 | F74: 0 | H74: 10 | I74: 0 | K74: 10 | L74: 0
A75: 501506007 | B75: 成功鎮 | C75: 成功海濱公園 | D75: 30 | E75: 4 | F75: 5 | H75: 4 | I75: 5 | K75: 4 | L75: 5
A76: 501509001 | B76: 東河鄉 | C76: 都蘭舊糖廠 | D76: 28 | E76: 6 | F76: 4 | H76: 6 | I76: 4 | K76: 6 | L76: 4
A77: 501509002 | B77: 東河鄉 | C77: 東河消防隊 | D77: 20 | E77: 3 | F77: 0 | H77: 3 | I77: 0 | K77: 3 | L77: 0
A78: 501506004 | B78: 成功鎮 | C78: 成功消防隊 | D78: 28 | E78: 4 | F78: 2 | H78: 4 | I78: 2 | K78: 4 | L78: 2
D79: =SUM(D69:D78) -> 230 | E79: =SUM(E69:E78) -> 49 | F79: =SUM(F69:F78) -> 17 | G79: =SUM(G69:G77) -> 0 | H79: =SUM(H69:H78) -> 51 | I79: =SUM(I69:I78) -> 17 | J79: =SUM(J69:J77) -> 0 | K79: =SUM(K69:K78) -> 51 | L79: =SUM(L69:L78) -> 17 | M79: =SUM(M69:M77) -> 0

Sheet D1平日
A1: D1 | B1: 行政區 | C1: 場站名稱 | D1: 合約柱數 | E1: 夜班配置(平日) | G1: 2.0綁車 | H1: 早班配置(平日) | J1: 2.0綁車 | K1: 晚班配置(平日) | M1: 2.0綁車
A2: 501501001 | B2: 台東市 | C2: 臺東縣政府文化處圖書館 | D2: 55 | E2: 5 | F2: 15 | H2: 2 | I2: 8 | K2: 2 | L2: 8
A3: 501501002 | B3: 台東市 | C3: 臺東轉運站 | D3: 60 | E3: 10 | F3: 10 | H3: 5 | I3: 10 | K3: 5 | L3: 10
A4: 501501003 | B4: 台東市 | C4: 臺東市公所 | D4: 20 | E4: 5 | F4: 5 | H4: 2 | I4: 5 | K4: 2 | L4: 5
A5: 501501004 | B5: 台東市 | C5: 臺東縣政府 | D5: 25 | E5: 5 | F5: 5 | H5: 2 | I5: 5 | K5: 2 | L5: 5
A6: 501501006 | B6: 台東市 | C6: 微光市集 | D6: 30 | E6: 5 | F6: 5 | H6: 3 | I6: 5 | K6: 3 | L6: 5
A7: 501501008 | B7: 台東市 | C7: 臺東縣立體育場 | D7: 20 | E7: 4 | F7: 4 | H7: 2 | I7: 3 | K7: 2 | L7: 3
A8: 501501009 | B8: 台東市 | C8: 東海國宅 | D8: 17 | E8: 5 | F8: 5 | H8: 5 | I8: 5 | K8: 2 | L8: 3
A9: 501501010 | B9: 台東市 | C9: 東海運動公園 | D9: 15 | E9: 4 | F9: 4 | H9: 2 | I9: 4 | K9: 2 | L9: 3
A10: 501501011 | B10: 台東市 | C10: 臺東火車站 | D10: 50 | E10: 10 | F10: 20 | H10: 10 | I10: 20 | K10: 10 | L10: 20
A11: 501501012 | B11: 台東市 | C11: 臺東棒球村第一棒球場 | D11: 20 | E11: 4 | F11: 4 | H11: 2 | I11: 4 | K11: 2 | L11: 4
A12: 501501013 | B12: 台東市 | C12: 寶桑國中活動中心 | D12: 15 | E12: 3 | F12: 3 | H12: 5 | I12: 5 | J12: 10 | K12: 5 | L12: 5 | M12: 10
A13: 501501014 | B13: 台東市 | C13: 生日蛋糕公園 | D13: 18 | E13: 4 | F13: 4 | H13: 4 | I13: 4 | K13: 4 | L13: 4
A14: 501501015 | B14: 台東市 | C14: 國立臺東女子高級中學 | D14: 39 | E14: 10 | F14: 5 | G14: 10 | H14: 20 | I14: 10 | J14: 30 | K14: 20 | L14: 10 | M14: 30
A15: 501501016 | B15: 台東市 | C15: 仁義北路與豐里橋交叉口 | D15: 20 | E15: 5 | F15: 5 | H15: 2 | I15: 5 | K15: 3 | L15: 3
A16: 501501017 | B16: 台東市 | C16: 臺東公園 | D16: 20 | E16: 4 | F16: 4 | H16: 2 | I16: 4 | K16: 2 | L16: 4
A17: 501501018 | B17: 台東市 | C17: 兒福聯盟臺東工作站 | D17: 27 | E17: 5 | F17: 5 | H17: 2 | I17: 5 | K17: 2 | L17: 5
A18: 501501019 | B18: 台東市 | C18: 國立臺東高級商業職業學校 | D18: 15 | E18: 4 | F18: 4 | H18: 3 | I18: 4 | J18: 10 | K18: 3 | L18: 4 | M18: 10
A19: 501501021 | B19: 台東市 | C19: 寶桑國小 | D19: 15 | E19: 4 | F19: 4 | H19: 3 | I19: 5 | K19: 3 | L19: 5
A20: 501501022 | B20: 台東市 | C20: 臺東縣環境保護局 | D20: 15 | E20: 4 | F20: 4 | H20: 2 | I20: 4 | K20: 2 | L20: 4
A21: 501501023 | B21: 台東市 | C21: 臺東市漢中街公園 | D21: 12 | E21: 3 | F21: 3 | H21: 2 | I21: 3 | K21: 2 | L21: 3
A22: 501501024 | B22: 台東市 | C22: 臺東聖母醫院 | D22: 18 | E22: 3 | F22: 3 | H22: 3 | I22: 3 | K22: 3 | L22: 3
A23: 501501025 | B23: 台東市 | C23: 柳州街停車場 | D23: 20 | E23: 7 | F23: 7 | H23: 7 | I23: 7 | K23: 2 | L23: 2
A24: 501501026 | B24: 台東市 | C24: 仁義北路河堤涼亭 | D24: 20 | E24: 4 | F24: 4 | H24: 2 | I24: 4 | K24: 2 | L24: 4
A25: 501501027 | B25: 台東市 | C25: 國立臺東高級中學學生宿舍 | D25: 20 | E25: 6 | F25: 5 | H25: 2 | I25: 5 | K25: 2 | L25: 5
A26: 501501029 | B26: 台東市 | C26: 桂林南路238巷與中華路一段719巷口 | D26: 18 | E26: 2 | F26: 2 | H26: 4 | I26: 4 | J26: 15 | K26: 4 | L26: 4 | M26: 15
A27: 501501030 | B27: 台東市 | C27: 臺東縣私立公東高級工業職業學校 | D27: 20 | E27: 4 | F27: 4 | H27: 4 | I27: 4 | K27: 4 | L27: 4
A28: 501501031 | B28: 台東市 | C28: 四維夜市 | D28: 17 | E28: 4 | F28: 4 | H28: 4 | I28: 3 | K28: 4 | L28: 3
A29: 501501032 | B29: 台東市 | C29: 四維路三段與傳廣路交叉口 | D29: 16 | E29: 4 | F29: 4 | H29: 2 | I29: 3 | K29: 2 | L29: 3
A30: 501501033 | B30: 台東市 | C30: 四維路三段與泰安街(西側) | D30: 20 | E30: 4 | F30: 4 | H30: 2 | I30: 3 | K30: 2 | L30: 3
A31: 501501034 | B31: 台東市 | C31: 開封街鐵馬道 | D31: 12 | E31: 5 | F31: 4 | H31: 5 | I31: 4 | K31: 5 | L31: 4
A32: 501501035 | B32: 台東市 | C32: 四維路三段與長安街交叉口 | D32: 13 | E32: 3 | F32: 3 | H32: 4 | I32: 3 | J32: 10 | K32: 4 | L32: 3 | M32: 10
A33: 501501036 | B33: 台東市 | C33: 臺東縣立新生國民中學 | D33: 23 | E33: 4 | F33: 4 | H33: 8 | I33: 7 | J33: 10 | K33: 8 | L33: 7 | M33: 10
A34: 501501037 | B34: 台東市 | C34: 臺東縣臺東市康樂國小 | D34: 20 | E34: 4 | F34: 4 | H34: 2 | I34: 4 | K34: 2 | L34: 4
A35: 501501038 | B35: 台東市 | C35: 臺東專科學校宿舍 | D35: 15 | E35: 6 | F35: 6 | G35: 8 | H35: 6 | I35: 6 | J35: 8 | K35: 6 | L35: 6 | M35: 8
A36: 501501039 | B36: 台東市 | C36: 臺東專科學校 | D36: 30 | E36: 2 | F36: 2 | H36: 1 | I36: 20 | J36: 10+10 | K36: 1 | L36: 20 | M36: 10+10
A37: 501501040 | B37: 台東市 | C37: 正氣公園 | D37: 16 | E37: 3 | F37: 3 | H37: 3 | I37: 3 | K37: 3 | L37: 3
A38: 501501041 | B38: 台東市 | C38: 長沙街溜冰場 | D38: 28 | E38: 8 | F38: 8 | H38: 6 | I38: 6 | K38: 6 | L38: 6
A39: 501501042 | B39: 台東市 | C39: 臺東航空站 | D39: 20 | E39: 4 | F39: 4 | H39: 4 | I39: 4 | K39: 4 | L39: 4
A40: 501501043 | B40: 台東市 | C40: 娜路彎大酒店 | D40: 30 | E40: 5 | F40: 10 | H40: 5 | I40: 5 | K40: 5 | L40: 5
...

Sheet D1假日
A1: D1 | B1: 行政區 | C1: 場站名稱 | D1: 合約柱數 | E1: 夜班配置(假日) | G1: 2.0綁車 | H1: 早班配置(假日) | J1: 2.0綁車 | K1: 晚班配置(假日) | M1: 2.0綁車
A2: 501501001 | B2: 台東市 | C2: 臺東縣政府文化處圖書館 | D2: 55 | E2: 5 | F2: 15 | H2: 5 | I2: 15 | K2: 5 | L2: 15
A3: 501501002 | B3: 台東市 | C3: 臺東轉運站 | D3: 60 | E3: 10 | F3: 20 | H3: 10 | I3: 20 | K3: 10 | L3: 20
A4: 501501003 | B4: 台東市 | C4: 臺東市公所 | D4: 20 | E4: 5 | F4: 5 | H4: 5 | I4: 5 | K4: 4 | L4: 5
A5: 501501004 | B5: 台東市 | C5: 臺東縣政府 | D5: 25 | E5: 5 | F5: 8 | H5: 5 | I5: 8 | K5: 5 | L5: 8
A6: 501501006 | B6: 台東市 | C6: 微光市集 | D6: 30 | E6: 5 | F6: 5 | H6: 5 | I6: 5 | K6: 3 | L6: 10
A7: 501501008 | B7: 台東市 | C7: 臺東縣立體育場 | D7: 20 | E7: 3 | F7: 3 | H7: 3 | I7: 3 | K7: 3 | L7: 3
A8: 501501009 | B8: 台東市 | C8: 東海國宅 | D8: 17 | E8: 5 | F8: 5 | H8: 5 | I8: 5 | K8: 5 | L8: 5
A9: 501501010 | B9: 台東市 | C9: 東海運動公園 | D9: 15 | E9: 4 | F9: 4 | H9: 4 | I9: 4 | K9: 3 | L9: 4
A10: 501501011 | B10: 台東市 | C10: 臺東火車站 | D10: 50 | E10: 10 | F10: 25 | H10: 10 | I10: 25 | K10: 5 | L10: 25
A11: 501501012 | B11: 台東市 | C11: 臺東棒球村第一棒球場 | D11: 20 | E11: 4 | F11: 4 | H11: 5 | I11: 5 | K11: 5 | L11: 5
A12: 501501013 | B12: 台東市 | C12: 寶桑國中活動中心 | D12: 15 | E12: 4 | F12: 4 | H12: 4 | I12: 4 | K12: 5 | L12: 5
A13: 501501014 | B13: 台東市 | C13: 生日蛋糕公園 | D13: 18 | E13: 4 | F13: 4 | H13: 3 | I13: 3 | K13: 4 | L13: 4
... A43: 501501046 | B43: 台東市 | C43: 國立臺灣史前文化博物館 | D43: 30 | E43: 5 | F43: 5 | H43: 5 | I43: 5 | K43: 5 | L43: 5
A44: 501501047 | B44: 台東市 | C44: 臺東大學附屬體育高級中學 | D44: 20 | E44: 2 | F44: 13 | G44: 15 | H44: 2 | I44: 13 | J44: 15 | K44: 2 | L44: 13 | M44: 15
A45: 501501048 | B45: 台東市 | C45: 臺東表演藝術創生基地 | D45: 20 | E45: 5 | F45: 5 | H45: 5 | I45: 5 | K45: 3 | L45: 3
A46: 501501049 | B46: 台東市 | C46: 臺東市新生國民小學 | D46: 16 | E46: 3 | F46: 3 | H46: 3 | I46: 3 | K46: 3 | L46: 3
A47: 501501050 | B47: 台東市 | C47: 北町日式宿舍 | D47: 16 | E47: 3 | F47: 3 | H47: 3 | I47: 3 | K47: 4 | L47: 4
A48: 501501051 | B48: 台東市 | C48: 國立臺東大學知本校區正門 | D48: 30 | E48: 5 | F48: 5 | H48: 5 | I48: 5 | K48: 5 | L48: 5
A49: 501501052 | B49: 台東市 | C49: 卑南遺址公園 | D49: 31 | E49: 3 | F49: 3 | H49: 3 | I49: 3 | K49: 3 | L49: 3
A50: 501501053 | B50: 台東市 | C50: 新興路與北安路52巷口 | D50: 20 | E50: 6 | F50: 6 | H50: 4 | I50: 4 | K50: 4 | L50: 4
A51: 501501054 | B51: 台東市 | C51: 知本火車站 | D51: 30 | E51: 5 | F51: 8 | H51: 5 | I51: 8 | K51: 5 | L51: 8
A52: 501501055 | B52: 台東市 | C52: 臺東市仁愛國民小學 | D52: 25 | E52: 5 | F52: 8 | H52: 4 | I52: 8 | K52: 4 | L52: 8
A53: 501501056 | B53: 台東市 | C53: 南一街與南一街113巷口 | D53: 20 | E53: 4 | F53: 4 | H53: 4 | I53: 4 | K53: 4 | L53: 4
A54: 501501057 | B54: 台東市 | C54: 馬蘭部落更生聚會所 | D54: 18 | E54: 6 | F54: 0 | H54: 6 | I54: 0 | K54: 6 | L54: 0
A55: 501501058 | B55: 台東市 | C55: 統冠聯合超市(臺東店) | D55: 15 | E55: 3 | F55: 3 | H55: 3 | I55: 3 | K55: 3 | L55: 3
A56: 501501059 | B56: 台東市 | C56: 寶桑里活動中心 | D56: 22 | E56: 5 | F56: 5 | H56: 5 | I56: 5 | K56: 5 | L56: 5
... A81: 501501089 | B81: 台東市 | C81: 衡陽路151巷口 | D81: 19 | E81: 4 | F81: 4 | H81: 4 | I81: 4 | K81: 4 | L81: 4
A82: 501501091 | B82: 台東市 | C82: 復興路128號 | D82: 16
A83: 501502002 | B83: 卑南鄉 | C83: 臺東戶政事務所卑南辦公室 | D83: 17 | E83: 5 | F83: 0 | H83: 5 | I83: 0 | K83: 5 | L83: 0
A84: 501502004 | B84: 卑南鄉 | C84: 7-11東遊季門市 | D84: 20 | E84: 6 | F84: 6 | H84: 6 | I84: 6 | K84: 6 | L84: 6
